Workbook
Name APP: 人物卡!$BZ$11
Name APPA: 人物卡!$BZ$12
Name apple: 人物卡!#REF!
Name arti: 人物卡!$CM$57
Name arting: 人物卡!$CA$57
Name blast: 人物卡!$BQ$39
Name Blasting: 人物卡!$BE$39
Name BMI: 附表!$I$63
Name CON: 人物卡!$BT$11
Name CONA: 人物卡!$BT$12
Name dbf: 人物卡!$BQ$63
Name dbfg: 人物卡!$BG$63
Name dbfi: 人物卡!$BQ$64
Name dbfig: 人物卡!$BG$64
Name dbo: 人物卡!$BQ$60
Name dbog: 人物卡!$BG$60
Name dbt: 人物卡!$BQ$61
Name dbtg: 人物卡!$BG$61
Name dbth: 人物卡!$BQ$62
Name dbthg: 人物卡!$BG$62
Name DEX: 人物卡!$BZ$9
Name DEXA: 人物卡!$BZ$10
Name EDU: 人物卡!$CF$11
Name EDUA: 人物卡!$CF$12
Name elmaing: 人物卡!$BE$36
Name fight: 人物卡!$BQ$59
Name fighting: 人物卡!$BG$59
Name hp: 人物卡!$BD$19
Name INT: 人物卡!$BZ$13
Name INTA: 人物卡!$BZ$14
Name Luck: 人物卡!$CF$13
Name LuckA: 人物卡!$CF$14
Name mema: 人物卡!$BQ$35
Name memaing: 人物卡!$BE$35
Name MP: 人物卡!$BV$19
Name pistol: 人物卡!$CM$59
Name pistoling: 人物卡!$CC$59
Name POW: 人物卡!$CF$9
Name POWA: 人物卡!$CF$10
Name SAN: 人物卡!$BM$19
Name shf: 人物卡!$CM$63
Name shfg: 人物卡!$CC$63
Name shfi: 人物卡!$CM$64
Name shfig: 人物卡!$CC$64
Name sho: 人物卡!$CM$60
Name shog: 人物卡!$CC$60
Name sht: 人物卡!$CM$61
Name shtg: 人物卡!$CC$61
Name shth: 人物卡!$CM$62
Name shthg: 人物卡!$CC$62
Name SIZ: 人物卡!$BT$13
Name SIZA: 人物卡!$BT$14
Name STR: 人物卡!$BT$9
Name STRA: 人物卡!$BT$10
Name throw: 人物卡!$CM$58
Name throwing: 人物卡!$CA$58
Name 阿尔巴尼亚: 附表!$BI$109:$EJ$109
Name 阿尔及利亚: 附表!$BI$136:$EJ$136
Name 阿富汗: 附表!$BI$48:$EJ$48
Name 阿根廷: 附表!$BI$220:$EJ$220

Sheet 人物卡
BA1: 玩家 | BC1: 姓名 | BH1: 关系 | BM1: 地点 | BS1: 模组 | BY1: 联系人 | CA1: 姓名 | CF1: 关系 | CK1: 地点 | CQ1: 模组
BC2: 例：辛永梅 | BH2: =_xlfn.XLOOKUP(BC2,成长经历!B34:B71,成长经历!K34:K71) -> 好友 | BM2: =_xlfn.XLOOKUP(BC2,成长经历!B34:B71,成长经历!F34:F71) -> 中国上海电车 | BS2: =_xlfn.XLOOKUP(BC2,成长经历!B34:B71,成长经历!U34:U71) -> 兴海之路（常暗） | CA2: 例：比尔·季默李 | CF2: =_xlfn.XLOOKUP(CA2,成长经历!AA34:AA71,成长经历!AJ34:AJ71) -> 信仰启发者 | CK2: =_xlfn.XLOOKUP(CA2,成长经历!AA34:AA71,成长经历!AE34:AE71) -> 美国牡丹丘 | CQ2: =_xlfn.XLOOKUP(CA2,成长经历!AA34:AA71,成长经历!AT34:AT71) -> 牡丹丘之泪···
BA3: 神话/可憎 | BD3: 伪名 | BH3: 实名 | BL3: SC检定 | BP3: SC减免 | BR3: 免疫 | BT3: 初次目击 | BY3: 旧日/外神 | CB3: 称号 | CF3: 名讳 | CJ3: SC检定 | CN3: SC减免 | CP3: 免疫 | CR3: 初次目击
BH4: =IF(BD4="","",_xlfn.XLOOKUP(BD4,成长经历!B77:B113,成长经历!G77:G113)) | BL4: =IF(BD4="","",_xlfn.XLOOKUP(BD4,成长经历!B77:B113,成长经历!L77:L113)) | BP4: =IF(BD4="","",_xlfn.XLOOKUP(BD4,成长经历!B77:B113,成长经历!Q77:Q113)) | BR4: =_xlfn.XLOOKUP(BD4,成长经历!B77:B113,成长经历!S77:S113) -> ☐ | BT4: =IF(BD4="","",_xlfn.XLOOKUP(BD4,成长经历!B77:B113,成长经历!U77:U113)) | CF4: =IF(CB4="","",_xlfn.XLOOKUP(CB4,成长经历!AB77:AB113,成长经历!AG77:AG113)) | CJ4: =IF(CB4="","",_xlfn.XLOOKUP(CB4,成长经历!AB77:AB113,成长经历!AL77:AL113)) | CN4: =IF(CB4="","",_xlfn.XLOOKUP(CB4,成长经历!AB77:AB113,成长经历!AQ77:AQ113)) | CP4: =_xlfn.XLOOKUP(CB4,成长经历!AB77:AB113,成长经历!AS77:AS113) -> ☐ | CR4: =IF(CB4="","",_xlfn.XLOOKUP(CB4,成长经历!AB77:AB113,成长经历!AU77:AU113))
BA5: 博览 群书 | BC5: 书名 | BF5: 实名 | BI5: 类别 | BK5: 技能 | BM5: 等级 | BO5: 耗时 | BQ5: 消耗 | BT5: 受益 | BV5: 语言 | BY5: 非凡 能力 | CA5: 别名 | CD5: 实名 | CG5: 分类 | CJ5: 消耗 | CN5: 用时 | CQ5: 条件
BF6: =IF(BC6="","",_xlfn.XLOOKUP(BC6,成长经历!B119:B155,成长经历!F119:F155)) | BI6: =IF(BC6="","",_xlfn.XLOOKUP(BC6,成长经历!B119:B155,成长经历!J119:J155)) | BK6: =IF(BC6="","",_xlfn.XLOOKUP(BC6,成长经历!B119:B155,成长经历!M119:M155)) | BM6: =IF(BC6="","",_xlfn.XLOOKUP(BC6,成长经历!B119:B155,成长经历!O119:O155)) | BO6: =IF(BC6="","",_xlfn.XLOOKUP(BC6,成长经历!B119:B155,成长经历!R119:R155)) | BQ6: =IF(BC6="","",_xlfn.XLOOKUP(BC6,成长经历!B119:B155,成长经历!U119:U155)) | BT6: =IF(AD134="","",XLOOKUP(AD134,成长经历!BA32:BA68,成长经历!BW32:BW68) | BV6: =IF(BC6="","",_xlfn.XLOOKUP(BC6,成长经历!B119:B155,成长经历!AC119:AC155)) | CD6: =IF(CA6="","",_xlfn.XLOOKUP(CA6,成长经历!BA35:BA71,成长经历!BE35:BE71,"")) | CG6: =IF(CA6="","",_xlfn.XLOOKUP(CA6,成长经历!BA35:BA71,成长经历!BI35:BI71,"")) | CJ6: =IF(CA6="","",_xlfn.XLOOKUP(CA6,成长经历!BA35:BA71,成长经历!BE35:BE71,"")) | CN6: =IF(CA6="","",_xlfn.XLOOKUP(CA6,成长经历!BA35:BA71,成长经历!BK35:BK71,"")) | CQ6: =IF(CA6="","",_xlfn.XLOOKUP(CA6,成长经历!BA35:BA71,成长经历!BT35:BT71,""))
BA7: 电脑推荐使用excel2010及以后版本或WPS打开本卡，使用横轴滚动条可以看见更多东西
A8: 行/列可以取消隐藏,手机版点击"行/列"字母，选择"行列操作"，之后选择"管理隐藏行列"，最后展开第一栏。 | BA8: 调查员信息 | BI8: =附表!BB53 -> 基本信息未填写！ | BR8: 年龄补正： | BU8: =附表!D37 -> 请和kp商议 | BZ8: 属性 | CB8: 含运 | CD8: =BT9+BT11+BT13+BZ9+BZ11+BZ13+CF9+CF11+CF13 -> 0 | CF8: 不含 | CH8: =CD8-CF13 -> 0 | CK8: 调查员肖像 | CT8: =SUM(AR12:AS22) -> 0 | DB8: =SUM(AR25:AS104) -> 0
BA9: 姓名 | BR9: 力量 STR | BV9: =IFERROR(INT(STRA/2),0) -> 0 | BX9: 敏捷 DEX | CB9: =IFERROR(INT(DEXA/2),0) -> 0 | CD9: 意志 POW | CH9: =IFERROR(INT(POWA/2),0) -> 0 | CT9: 您的角色可能（只是可能！）
BA10: 玩家 | BI10: 时代 | BL10: 1920s | BT10: =IF(STR="","未填写",AT12) -> 未填写 | BV10: =IFERROR(INT(STRA/5),0) -> 0 | BZ10: =IF(DEX="","未填写",AT15) -> 未填写 | CB10: =IFERROR(INT(DEXA/5),0) -> 0 | CF10: =IF(POW="","未填写",AT18) -> 未填写 | CH10: =IFERROR(INT(POWA/5),0) -> 0 | CT10: =IF(OR(SIZ=0,STR=0,DEX=0),"","BMI:"&BMI&" "&附表!I64) | DB10: =IF(OR(SIZ=0,STR=0,DEX=0),"","身高："&附表!L63&"米") | DJ10: =IF(OR(SIZ=0,STR=0,DEX=0),"","体重："&附表!K63&"千克")
B11: 模组名 | E11: 模组名 | H11: 模组名 | K11: 模组名 | N11: 模组名 | Q11: 模组名 | T11: 模组名 | W11: 模组名 | Z11: 模组名 | AC11: 模组名 | AF11: 模组名 | AI11: 模组名 | AL11: 模组名 | AO11: 模组名 | AR11: 成长 | AT11: 总计 | AV11: 属性 | AY11: 修正 | BA11: 职业 | BI11: 职业序号 | BR11: 体质 CON | BV11: =IFERROR(INT(CONA/2),0) -> 0 | BX11: 外貌 APP | CB11: =IFERROR(INT(APPA/2),0) -> 0 | CD11: 教育 知识 | CH11: =IFERROR(INT(EDUA/2),0) -> 0
C12: - | F12: - | I12: - | L12: - | O12: - | R12: - | U12: - | X12: - | AA12: - | AD12: - | AG12: - | AJ12: - | AM12: - | AP12: - | AR12: =SUM(AO12,AL12,AI12,AF12,AC12,Z12,W12,T12,Q12,N12,K12,H12,E12,B12)-SUM(AQ12,AN12,AK12,AH12,AE12,AB12,Y12,V12,S12,P12,M12,J12,G12,D12) -> 0 | AT12: =AR12+STR -> 0 | AV12: 力量 | AY12: =IF(AR12>0,"强身",IF(AR12<0,"衰弱","")) | BA12: 年龄 | BD12: =CQ92 -> 时间未填 | BI12: 性别 | BT12: =IF(CON="","未填写",AT13) -> 未填写 | BV12: =IFERROR(INT(CONA/5),0) -> 0 | BZ12: =IF(APP="","未填写",AT16) -> 未填写 | CB12: =IFERROR(INT(APPA/5),0) -> 0 | CF12: =IF(EDU="","未填写",AT19) -> 未填写 | CH12: =IFERROR(INT(EDUA/5),0) -> 0 | CT12: =IF(STRA="未填写","",IF(STRA=0,"",IF(STRA<=15,"虚弱，孱弱",IF(STRA<=40,"力量弱小",IF(STRA<=60,"有正常人的力量",IF(STRA<=80,"超乎常人的力量",IF(STRA<100,"超乎超乎常人的力量","奥运举重冠军，人类极限！"))))))) | DB12: =IF(DEXA="未填写","",IF(DEXA=0,"",IF(DEXA<=20,"很不灵活",IF(DEXA<=40,"不是很灵活",IF(DEXA<=60,"普通人水平",IF(DEXA<=80,"是一位运动健将",IF(DEXA<100,"高速而灵活,可以达成超凡的技艺","超越人类极限的反应力！"))))))) | DJ12: =IF(POWA="未填写","",IF(POWA=0,"",IF(POWA<=20,"尔不过玩物",IF(POWA<=40,"痴愚盲目",IF(POWA<=60,"如常人一般会有一定自制力",IF(POWA<=80,"我心如铁，心坚石穿",IF(POWA<100,"泰山崩于面而色不变",IF(POWA<140,"钢铁之心，还能看见鬼","基本是异界生物"))))))))
C13: - | F13: - | I13: - | L13: - | O13: - | R13: - | U13: - | X13: - | AA13: - | AD13: - | AG13: - | AJ13: - | AM13: - | AP13: - | AR13: =SUM(AO13,AL13,AI13,AF13,AC13,Z13,W13,T13,Q13,N13,K13,H13,E13,B13)-SUM(AQ13,AN13,AK13,AH13,AE13,AB13,Y13,V13,S13,P13,M13,J13,G13,D13) -> 0 | AT13: =AR13+CON -> 0 | AV13: 体质 | AY13: =IF(AR13>0,"健体",IF(AR13<0,"衰弱","")) | BA13: 国籍 | BI13: 货币 | BL13: 美元 | BR13: 体型 SIZ | BV13: =IFERROR(INT(SIZA/2),0) -> 0 | BX13: 智力 灵感 | CB13: =IFERROR(INT(INTA/2),0) -> 0 | CD13: 幸运 Luck | CH13: =IFERROR(INT(LuckA/2),0) -> 0
C14: - | F14: - | I14: - | L14: - | O14: - | R14: - | U14: - | X14: - | AA14: - | AD14: - | AG14: - | AJ14: - | AM14: - | AP14: - | AR14: =SUM(AO14,AL14,AI14,AF14,AC14,Z14,W14,T14,Q14,N14,K14,H14,E14,B14)-SUM(AQ14,AN14,AK14,AH14,AE14,AB14,Y14,V14,S14,P14,M14,J14,G14,D14) -> 0 | AT14: =AR14+SIZ -> 0 | AV14: 体型 | AY14: =IF(AR14>0,"壮硕",IF(AR14<0,"苗条","")) | BA14: 住地 | BI14: 故乡 | BT14: =IF(SIZ="","未填写",AT14) -> 未填写 | BV14: =IFERROR(INT(SIZA/5),0) -> 0 | BZ14: =IF(INT="","未填写",AT17) -> 未填写 | CB14: =IFERROR(INT(INTA/5),0) -> 0 | CF14: =IF(Luck="","未改运",AT20) -> 未改运 | CH14: =IFERROR(INT(LuckA/5),0) -> 0 | CT14: =IF(CONA="未填写","",IF(CONA=0,"",IF(CONA<=20,"常年患病在身",IF(CONA<=40,"体弱多病",IF(CONA<=60,"不会生什么大毛病",IF(CONA<=80,"健硕，浑身湿透也不会感冒",IF(CONA<100,"身体素质极好，精神抖擞","钢铁之躯，人类极限！"))))))) | DB14: =IF(APPA="未填写","",IF(APPA=0,"",IF(APPA<=20,"用脸就能恐惧敌人。。或队友",IF(APPA<=40,"有些难看",IF(APPA<=60,"人群之中谁也不会看你一眼之后就忘不掉你容颜",IF(APPA<=80,"五官端正，仪表堂堂",IF(APPA<100,"沉鱼落雁，闭月羞花","古神之容貌"))))))) | DJ14: =IF(EDUA="未填写","",IF(EDUA=0,"",IF(EDUA<=20,"目不识丁",IF(EDUA<=40,"小学毕业",IF(EDUA<=50,"高中毕业",IF(EDUA<=60,"普通大学生",IF(EDUA<70,"重点大学的普通学生，或是普通大学的研究生",IF(EDUA<80,"重点大学的高材生",IF(EDUA<96,"经验丰富的研究生",IF(EDUA<100,"教授，博士","世界级权威!"))))))))))
C15: - | F15: - | I15: - | L15: - | O15: - | R15: - | U15: - | X15: - | AA15: - | AD15: - | AG15: - | AJ15: - | AM15: - | AP15: - | AR15: =SUM(AO15,AL15,AI15,AF15,AC15,Z15,W15,T15,Q15,N15,K15,H15,E15,B15)-SUM(AQ15,AN15,AK15,AH15,AE15,AB15,Y15,V15,S15,P15,M15,J15,G15,D15) -> 0 | AT15: =AR15+DEX -> 0 | AV15: 敏捷 | AY15: =IF(AR15>0,"加速",IF(AR15<0,"减速","")) | BR15: 上方填写属性的初始值，属性成长可前往左表 上方、左方皆有隐藏行列，可以展开查看下拉栏与成长表
C16: - | F16: - | I16: - | L16: - | O16: - | R16: - | U16: - | X16: - | AA16: - | AD16: - | AG16: - | AJ16: - | AM16: - | AP16: - | AR16: =SUM(AO16,AL16,AI16,AF16,AC16,Z16,W16,T16,Q16,N16,K16,H16,E16,B16)-SUM(AQ16,AN16,AK16,AH16,AE16,AB16,Y16,V16,S16,P16,M16,J16,G16,D16) -> 0 | AT16: =AR16+APP -> 0 | AV16: 外貌 | AY16: =IF(AR16>0,"进化",IF(AR16<0,"退化","")) | BA16: 组织 | BC16: =IF(BV157="","暂无组织",BV157) -> 暂无组织 | BI16: 任职 | BK16: =IF(BX159="","无职位",BX159) -> 无职位 | BM16: 经验 | BO16: =IF(BX160=0,"无",BX160) -> 无 | BP16: 年 | CT16: =IF(SIZA="未填写","",IF(SIZA=0,"",IF(SIZA<=20,"孩童，身短体瘦",IF(SIZA<=40,"乙女身材",IF(SIZA<=60,"普遍身高155-175",IF(SIZA<=80,"不是高就是胖",IF(SIZA<=100,"大号的人",IF(SIZA<150,"听说你正在申请身高世界记录？",IF(SIZA<180,"你可能是一头牛",IF(SIZA<200,"你已经是历史上最重的人类了","过分了喂！")))))))))) | DB16: =IF(INTA="未填写","",IF(INTA=0,"",IF(INTA<=20,"脑子是个好东西，可惜。。。",IF(INTA<=40,"理解知识要耗费比普通人更多的时间",IF(INTA<=60,"有着普通人的灵光一现",IF(INTA<=80,"可以自主进行发明创造",IF(INTA<90,"天才级水准",IF(INTA<99,"超凡之脑，能够理解多门语言与法则","超越人类之智，能够产生跨时代的想法！")))))))) | DJ16: =IF(LuckA="未改运","",IF(LuckA=0,"",IF(LuckA<=20,"克夫克妻",IF(LuckA<=40,"霉运连连",IF(LuckA<=60,"命格平庸",IF(LuckA<=80,"在马路边捡到100块",IF(LuckA<100,"被幸运女神所眷顾","凌驾于幸运女神之上")))))))
C17: - | F17: - | I17: - | L17: - | O17: - | R17: - | U17: - | X17: - | AA17: - | AD17: - | AG17: - | AJ17: - | AM17: - | AP17: - | AR17: =SUM(AO17,AL17,AI17,AF17,AC17,Z17,W17,T17,Q17,N17,K17,H17,E17,B17)-SUM(AQ17,AN17,AK17,AH17,AE17,AB17,Y17,V17,S17,P17,M17,J17,G17,D17) -> 0 | AT17: =AR17+INT -> 0 | AV17: 智力 | AY17: =IF(AR17>0,"汲取",IF(AR17<0,"散失","")) | BA17: 现时间 | BD17: 公元 | BJ17: 月 | BL17: 日 | BM17: 0
C18: - | F18: - | I18: - | L18: - | O18: - | R18: - | U18: - | X18: - | AA18: - | AD18: - | AG18: - | AJ18: - | AM18: - | AP18: - | AR18: =SUM(AO18,AL18,AI18,AF18,AC18,Z18,W18,T18,Q18,N18,K18,H18,E18,B18)-SUM(AQ18,AN18,AK18,AH18,AE18,AB18,Y18,V18,S18,P18,M18,J18,G18,D18) -> 0 | AT18: =AR18+POW -> 0 | AV18: 意志 | AY18: =IF(AR18>0,"强魂",IF(AR18<0,"衰志","")) | BA18: =IF(BE18=0,"","任意特长数：") | BE18: =INDEX(本职技能!$A$2:$IC$82,MATCH("任意特长",本职技能!$A$2:$A$87,0),MATCH($BL$11,本职技能!$A$1:$IC$1,0)) -> 0 | BJ18: =INDEX(本职技能!$A$2:$IC$82,MATCH("☆",本职技能!$A$2:$A$87,0),MATCH($BL$11,本职技能!$A$1:$IC$1,0)) -> 0 | BS18: =INDEX(本职技能!$A$2:$IC$82,MATCH("⊙",本职技能!$A$2:$A$87,0),MATCH($BL$11,本职技能!$A$1:$IC$1,0)) -> 0 | CB18: =INDEX(本职技能!$A$2:$IC$82,MATCH("☯",本职技能!$A$2:$A$87,0),MATCH($BL$11,本职技能!$A$1:$IC$1,0)) -> 0 | CK18: =INDEX(本职技能!$A$2:$IC$82,MATCH("※",本职技能!$A$2:$A$87,0),MATCH($BL$11,本职技能!$A$1:$IC$1,0)) -> 0 | CT18: 绝佳素质 | CU18: NO.1 | CW18: =_xlfn.XLOOKUP(DA18,$AT$12:$AT$22,$AV$12:$AV$22,,,1) -> 理智上限 | DA18: =LARGE($AT$12:$AU$22,1) -> 99 | DC18: 理智损 失倍率 | DF18: =IF(DH20="☑",0.5,1) -> 1
C19: - | F19: - | I19: - | L19: - | O19: - | R19: - | U19: - | X19: - | AA19: - | AD19: - | AG19: - | AJ19: - | AM19: - | AP19: - | AR19: =SUM(AO19,AL19,AI19,AF19,AC19,Z19,W19,T19,Q19,N19,K19,H19,E19,B19)-SUM(AQ19,AN19,AK19,AH19,AE19,AB19,Y19,V19,S19,P19,M19,J19,G19,D19) -> 0 | AT19: =AR19+EDU -> 0 | AV19: 教育 | AY19: =IF(AR19>0,"汲取",IF(AR19<0,"散失","")) | BA19: 生命值 HP | BD19: =IFERROR(BF19,"") -> 0 | BF19: =IFERROR(INT((CONA+SIZA)/10),0) -> 0 | BH19: 状态: | BJ19: 理智 Sanity | BM19: =IFERROR(AT21,"") -> 0 | BO19: =AT22 -> 99 | BQ19: 状态: | BS19: 魔法 MP | BV19: =IFERROR(BX19,"") -> 0 | BX19: =IFERROR(INT(POWA/5),0) -> 0 | BZ19: 每h恢复 | CB19: 移动力 MOV | CE19: =CH20+8 -> 8 | CH19: 调整值 | CJ19: 护甲 Armor | CM19: =IF($CM21=0,"0",VLOOKUP($CM21,'防具表 载具表'!B2:J82,2,FALSE)) -> 无 | CO19: 覆盖部位 | CU19: NO.2 | CW19: =_xlfn.XLOOKUP(DA19,$AT$12:$AT$22,$AV$12:$AV$22,,,-1) -> 理智 | DA19: =LARGE($AT$12:$AU$22,2) -> 0
C20: - | F20: - | I20: - | L20: - | O20: - | R20: - | U20: - | X20: - | AA20: - | AD20: - | AG20: - | AJ20: - | AM20: - | AP20: - | AR20: =SUM(AO20,AL20,AI20,AF20,AC20,Z20,W20,T20,Q20,N20,K20,H20,E20,B20)-SUM(AQ20,AN20,AK20,AH20,AE20,AB20,Y20,V20,S20,P20,M20,J20,G20,D20) -> 0 | AT20: =AR20+Luck -> 0 | AV20: 幸运 | AY20: =IF(AR20>0,"强运",IF(AR20<0,"弱运","")) | BH20: 健康 | BQ20: 清醒 | BZ20: =IFERROR(IF(POWA="","",INT(POWA/100+1)),"") | CH20: =附表!C9 -> 0 | CO20: =IF($CM21=0,"",VLOOKUP($CM21,'防具表 载具表'!B2:I101,4,FALSE)) -> —— | CU20: NO.3 | CW20: =VLOOKUP(DA20,$AT$12:$AX$22,3,FALSE) -> 力量 | DA20: =LARGE($AT$12:$AU$22,3) -> 0 | DC20: 精神固化 | DH20: ☐ | DJ20: 相信者 | DP20: ☐
C21: - | F21: - | I21: - | L21: - | O21: - | R21: - | U21: - | X21: - | AA21: - | AD21: - | AG21: - | AJ21: - | AM21: - | AP21: - | AR21: =SUM(AO21,AL21,AI21,AF21,AC21,Z21,W21,T21,Q21,N21,K21,H21,E21,B21)-SUM(AQ21,AN21,AK21,AH21,AE21,AB21,Y21,V21,S21,P21,M21,J21,G21,D21) -> 0 | AT21: =IFERROR(AR21+POWA,0) -> 0 | AV21: 理智 | AY21: =IF(AR21>0,"坚毅",IF(AR21<0,"衰退","")) | BA21: 重伤值: | BC21: =IFERROR(CEILING(BF19/2,1),"") -> 0 | BE21: 临时生命值： | BH21: 0 | BJ21: 今日损失 : | BM21: 0 | BO21: 剩余： | BQ21: =IFERROR(BM19-BM21,0) -> 0 | BS21: 用过的魔法： | CB21: 移动方式 | CD21: 步式 | CF21: 护甲减值 | CH21: 关 | CJ21: 护甲类型 : | CM21: 请看【防具表】 | CT21: 纯熟技艺 | CU21: NO.1 | CW21: =IFERROR(_xlfn.XLOOKUP(DA21,$AT$25:$AT$104,$AV$25:$AV$104,,,1),"") -> 急救 | DA21: =IFERROR(MAX(AT25:AU104),"") -> 30 | DC21: =IF(LEN(BV94)=0,"你的背景故事还没动笔哦","你共写了"&LEN(BV94)&"字的背景故事！") -> 你的背景故事还没动笔哦 | DT21: =成长经历!B115 -> 书籍是人类进步的阶梯，快去找本书看吧 | EF21: =成长经历!U115 -> 韦编三而绝，书读百遍，其义才能自现
AR22: =SUM(B22:AQ22) -> 0 | AT22: =99-BQ34+AR22 -> 99 | AV22: 理智上限 | AY22: =IF(AT22>99,"坚毅",IF(AT22<99,"衰退","")) | BA22: =IF(BL11=0," ","["&LOOKUP(BL11,职业列表!A2:A237,职业列表!B2:B237)&"]的本职技能："&LOOKUP(BL11,职业列表!A2:A237,职业列表!G2:G237)) | CU22: NO.2 | CW22: =IFERROR(_xlfn.XLOOKUP(DA22,$AT$25:$AT$104,$AV$25:$AV$104,,,-1),"") -> 侦查 | DA22: =IFERROR(LARGE($AT$25:$AU$104,2),"") -> 25 | DT22: =成长经历!K31 -> 你还未踏上旅途···
B23: 成长表 | BA23: 技能表 | CI23: =附表!M58 -> 母语未填写！ | CU23: NO.3 | CW23: =IFERROR(VLOOKUP(DA23,$AT$25:$AX$104,3,FALSE),"") -> 格斗:斗殴 | DA23: =IFERROR(LARGE($AT$25:$AU$104,3),"") -> 25 | DT23: =成长经历!B73 -> 你对世界的真相一无所知···
B24: 模组名 | E24: 模组名 | H24: 模组名 | K24: 模组名 | N24: 模组名 | Q24: 模组名 | T24: 模组名 | W24: 模组名 | Z24: 模组名 | AC24: 模组名 | AF24: 模组名 | AI24: 模组名 | AL24: 模组名 | AO24: 模组名 | AR24: 成长 | AT24: 总计 | AV24: 技能 | AY24: 本职 | BA24: 成功标 | BC24: 本职 | BE24: 技能名称 | BI24: 初始 | BK24: 成长 | BM24: 职业 | BO24: 兴趣 | BQ24: 成功率 普通/困难/极难 | BW24: 成功标 | BY24: 本职 | CA24: 技能名称 | CE24: 初始 | CG24: 成长 | CI24: 职业 | CK24: 兴趣 | CM24: 成功率 普通/困难/极难 | CT24: 你现在有这么多 | CZ24: 那么你分配到了哪里? | DT24: =成长经历!AI73 -> 你从未见过何为真正之绝望···
C25: - | F25: - | I25: - | L25: - | O25: - | R25: - | U25: - | X25: - | AA25: - | AD25: - | AG25: - | AJ25: - | AM25: - | AP25: - | AR25: =SUM(AO25,AL25,AI25,AF25,AC25,Z25,W25,T25,Q25,N25,K25,H25,E25,B25)-SUM(AQ25,AN25,AK25,AH25,AE25,AB25,Y25,V25,S25,P25,M25,J25,G25,D25) -> 0 | AT25: =AR25+BI25+BM26+BO25 -> 5 | AV25: =BE25 -> 会计 | AY25: =BC25 -> 0 | BA25: ☐ | BC25: =IF(ISTEXT(IFERROR(VLOOKUP(人物卡!BE25,人物卡!$DI$25:$DQ$29,1,FALSE),IFERROR(VLOOKUP(人物卡!BE25,人物卡!$CZ$25:$DB$29,1,FALSE),0))),"★",INDEX(本职技能!$A$2:$IC$87,MATCH(人物卡!BE25,本职技能!$A$2:$A$87,0),MATCH(人物卡!$BL$11,本职技能!$A$1:$IC$1,0))) -> 0 | BE25: 会计 | BI25: 5 | BK25: =AR25 -> 0 | BQ25: =SUM(BI25:BO25) -> 5 | BS25: =INT(BQ25/2) -> 2 | BU25: =INT(BQ25/5) -> 1 | BW25: ☐ | BY25: =IF(ISTEXT(IFERROR(VLOOKUP(人物卡!CA25,人物卡!$DI$25:$DQ$29,1,FALSE),IFERROR(VLOOKUP(人物卡!CA25,人物卡!$CZ$25:$DB$29,1,FALSE),0))),"★",INDEX(本职技能!$A$2:$IC$87,MATCH(人物卡!CA25,本职技能!$A$2:$A$87,0),MATCH(人物卡!$BL$11,本职技能!$A$1:$IC$1,0))) -> 0 | CA25: 锁匠 | CE25: 1 | CG25: =AR65 -> 0 | CM25: =SUM(CE25:CK25) -> 1 | CO25: =INT(CM25/2) -> 0 | CQ25: =INT(CM25/5) -> 0 | CT25: 任意特长 | DT25: =成长经历!R73 -> 你的理智防线还坚挺着···
C26: - | F26: - | I26: - | L26: - | O26: - | R26: - | U26: - | X26: - | AA26: - | AD26: - | AG26: - | AJ26: - | AM26: - | AP26: - | AR26: =SUM(AO26,AL26,AI26,AF26,AC26,Z26,W26,T26,Q26,N26,K26,H26,E26,B26)-SUM(AQ26,AN26,AK26,AH26,AE26,AB26,Y26,V26,S26,P26,M26,J26,G26,D26) -> 0 | AT26: =AR26+BI26+BM26+BO26 -> 5 | AV26: =BE26 -> 法律 | AY26: =BC26 -> 0 | BA26: ☐ | BC26: =IF(ISTEXT(IFERROR(VLOOKUP(人物卡!BE26,人物卡!$DI$25:$DQ$29,1,FALSE),IFERROR(VLOOKUP(人物卡!BE26,人物卡!$CZ$25:$DB$29,1,FALSE),0))),"★",INDEX(本职技能!$A$2:$IC$87,MATCH(人物卡!BE26,本职技能!$A$2:$A$87,0),MATCH(人物卡!$BL$11,本职技能!$A$1:$IC$1,0))) -> 0 | BE26: 法律 | BI26: 5 | BK26: =AR26 -> 0 | BQ26: =SUM(BI26:BO26) -> 5 | BS26: =INT(BQ26/2) -> 2 | BU26: =INT(BQ26/5) -> 1 | BW26: ☐ | BY26: =IF(ISTEXT(IFERROR(VLOOKUP(人物卡!CA26,人物卡!$DI$25:$DQ$29,1,FALSE),IFERROR(VLOOKUP(人物卡!CA26,人物卡!$CZ$25:$DB$29,1,FALSE),0))),"★",INDEX(本职技能!$A$2:$IC$87,MATCH(人物卡!CA26,本职技能!$A$2:$A$87,0),MATCH(人物卡!$BL$11,本职技能!$A$1:$IC$1,0))) -> 0 | CA26: 乔装 | CE26: 5 | CG26: =AR66 -> 0 | CM26: =SUM(CE26:CK26) -> 5 | CO26: =INT(CM26/2) -> 2 | CQ26: =INT(CM26/5) -> 1 | CT26: =附表!AD25 -> 无 | DT26: =成长经历!BA31 -> 超乎想象的能力，等待你窥探···
C27: - | F27: - | I27: - | L27: - | O27: - | R27: - | U27: - | X27: - | AA27: - | AD27: - | AG27: - | AJ27: - | AM27: - | AP27: - | AR27: =SUM(AO27,AL27,AI27,AF27,AC27,Z27,W27,T27,Q27,N27,K27,H27,E27,B27)-SUM(AQ27,AN27,AK27,AH27,AE27,AB27,Y27,V27,S27,P27,M27,J27,G27,D27) -> 0 | AT27: =AR27+BI27+BM27+BO27 -> 5 | AV27: =BE27 -> 历史 | AY27: =BC27 -> 0 | BA27: ☐ | BC27: =IF(ISTEXT(IFERROR(VLOOKUP(人物卡!BE27,人物卡!$DI$25:$DQ$29,1,FALSE),IFERROR(VLOOKUP(人物卡!BE27,人物卡!$CZ$25:$DB$29,1,FALSE),0))),"★",INDEX(本职技能!$A$2:$IC$87,MATCH(人物卡!BE27,本职技能!$A$2:$A$87,0),MATCH(人物卡!$BL$11,本职技能!$A$1:$IC$1,0))) -> 0 | BE27: 历史 | BI27: 5 | BK27: =AR27 -> 0 | BQ27: =SUM(BI27:BO27) -> 5 | BS27: =INT(BQ27/2) -> 2 | BU27: =INT(BQ27/5) -> 1 | BW27: ☐ | BY27: =IF(ISTEXT(IFERROR(VLOOKUP(人物卡!CA27,人物卡!$DI$25:$DQ$29,1,FALSE),IFERROR(VLOOKUP(人物卡!CA27,人物卡!$CZ$25:$DB$29,1,FALSE),0))),"★",INDEX(本职技能!$A$2:$IC$87,MATCH(人物卡!CA27,本职技能!$A$2:$A$87,0),MATCH(人物卡!$BL$11,本职技能!$A$1:$IC$1,0))) -> 0 | CA27: 妙手 | CE27: 10 | CG27: =AR67 -> 0 | CM27: =SUM(CE27:CK27) -> 10 | CO27: =INT(CM27/2) -> 5 | CQ27: =INT(CM27/5) -> 2 | DT27: =成长经历!BA73 -> 你接触到的还只是凡尘之物···
C28: - | F28: - | I28: - | L28: - | O28: - | R28: - | U28: - | X28: - | AA28: - | AD28: - | AG28: - | AJ28: - | AM28: - | AP28: - | AR28: =SUM(AO28,AL28,AI28,AF28,AC28,Z28,W28,T28,Q28,N28,K28,H28,E28,B28)-SUM(AQ28,AN28,AK28,AH28,AE28,AB28,Y28,V28,S28,P28,M28,J28,G28,D28) -> 0 | AT28: =AR28+BI28+BM28+BO28 -> 1 | AV28: =BE28 -> 人类学 | AY28: =BC28 -> 0 | BA28: ☐ | BC28: =IF(ISTEXT(IFERROR(VLOOKUP(人物卡!BE28,人物卡!$DI$25:$DQ$29,1,FALSE),IFERROR(VLOOKUP(人物卡!BE28,人物卡!$CZ$25:$DB$29,1,FALSE),0))),"★",INDEX(本职技能!$A$2:$IC$87,MATCH(人物卡!BE28,本职技能!$A$2:$A$87,0),MATCH(人物卡!$BL$11,本职技能!$A$1:$IC$1,0))) -> 0 | BE28: 人类学 | BI28: 1 | BK28: =AR28 -> 0 | BQ28: =SUM(BI28:BO28) -> 1 | BS28: =INT(BQ28/2) -> 0 | BU28: =INT(BQ28/5) -> 0 | BW28: ☐ | BY28: =IF(ISTEXT(IFERROR(VLOOKUP(人物卡!CA28,人物卡!$DI$25:$DQ$29,1,FALSE),IFERROR(VLOOKUP(人物卡!CA28,人物卡!$CZ$25:$DB$29,1,FALSE),0))),"★",INDEX(本职技能!$A$2:$IC$87,MATCH(人物卡!CA28,本职技能!$A$2:$A$87,0),MATCH(人物卡!$BL$11,本职技能!$A$1:$IC$1,0))) -> 0 | CA28: 潜行 | CE28: 20 | CG28: =AR68 -> 0 | CM28: =SUM(CE28:CK28) -> 20 | CO28: =INT(CM28/2) -> 10 | CQ28: =INT(CM28/5) -> 4 | DT28: =IF(COUNTA(BF69:BJ73)=0,"你目前手无寸铁","你共携带了"&COUNTA(BF69:BJ73)&"种武器！") -> 你目前手无寸铁 | EA28: =IF(COUNTA(BE99:BT113)=0,"你还没携带任何物品","你共携带了"&COUNTA(BE99:BJ107,BM99:BR107,BE85:BJ89,BM85:BR89)&"种物品！") -> 你还没携带任何物品
C29: - | F29: - | I29: - | L29: - | O29: - | R29: - | U29: - | X29: - | AA29: - | AD29: - | AG29: - | AJ29: - | AM29: - | AP29: - | AR29: =SUM(AO29,AL29,AI29,AF29,AC29,Z29,W29,T29,Q29,N29,K29,H29,E29,B29)-SUM(AQ29,AN29,AK29,AH29,AE29,AB29,Y29,V29,S29,P29,M29,J29,G29,D29) -> 0 | AT29: =AR29+BI29+BM29+BO29 -> 5 | AV29: =BE29 -> 估价 | AY29: =BC29 -> 0 | BA29: ☐ | BC29: =IF(ISTEXT(IFERROR(VLOOKUP(人物卡!BE29,人物卡!$DI$25:$DQ$29,1,FALSE),IFERROR(VLOOKUP(人物卡!BE29,人物卡!$CZ$25:$DB$29,1,FALSE),0))),"★",INDEX(本职技能!$A$2:$IC$87,MATCH(人物卡!BE29,本职技能!$A$2:$A$87,0),MATCH(人物卡!$BL$11,本职技能!$A$1:$IC$1,0))) -> 0 | BE29: 估价 | BI29: 5 | BK29: =AR29 -> 0 | BQ29: =SUM(BI29:BO29) -> 5 | BS29: =INT(BQ29/2) -> 2 | BU29: =INT(BQ29/5) -> 1 | BW29: ☐ | BY29: =IF(ISTEXT(IFERROR(VLOOKUP(人物卡!CA29,人物卡!$DI$25:$DQ$29,1,FALSE),IFERROR(VLOOKUP(人物卡!CA29,人物卡!$CZ$25:$DB$29,1,FALSE),0))),"★",INDEX(本职技能!$A$2:$IC$87,MATCH(人物卡!CA29,本职技能!$A$2:$A$87,0),MATCH(人物卡!$BL$11,本职技能!$A$1:$IC$1,0))) -> 0 | CA29: 图书馆使用 | CE29: 20 | CG29: =AR69 -> 0 | CM29: =SUM(CE29:CK29) -> 20 | CO29: =INT(CM29/2) -> 10 | CQ29: =INT(CM29/5) -> 4 | CT29: 提示当前职业 | DT29: ="你共点了"&COUNTA(BM26:BN33,BM35:BN64,CI25:CJ64)&"种职业技能！" -> 你共点了0种职业技能！ | EA29: ="你共点了"&COUNTA(CK25:CL64,BO35:BP64,BO25:BP33)&"种兴趣技能！" -> 你共点了0种兴趣技能！
C30: - | F30: - | I30: - | L30: - | O30: - | R30: - | U30: - | X30: - | AA30: - | AD30: - | AG30: - | AJ30: - | AM30: - | AP30: - | AR30: =SUM(AO30,AL30,AI30,AF30,AC30,Z30,W30,T30,Q30,N30,K30,H30,E30,B30)-SUM(AQ30,AN30,AK30,AH30,AE30,AB30,Y30,V30,S30,P30,M30,J30,G30,D30) -> 0 | AT30: =AR30+BI30+BM30+BO30 -> 1 | AV30: =BE30 -> 考古学 | AY30: =BC30 -> 0 | BA30: ☐ | BC30: =IF(ISTEXT(IFERROR(VLOOKUP(人物卡!BE30,人物卡!$DI$25:$DQ$29,1,FALSE),IFERROR(VLOOKUP(人物卡!BE30,人物卡!$CZ$25:$DB$29,1,FALSE),0))),"★",INDEX(本职技能!$A$2:$IC$87,MATCH(人物卡!BE30,本职技能!$A$2:$A$87,0),MATCH(人物卡!$BL$11,本职技能!$A$1:$IC$1,0))) -> 0 | BE30: 考古学 | BI30: 1 | BK30: =AR30 -> 0 | BQ30: =SUM(BI30:BO30) -> 1 | BS30: =INT(BQ30/2) -> 0 | BU30: =INT(BQ30/5) -> 0 | BW30: ☐ | BY30: =IF(ISTEXT(IFERROR(VLOOKUP(人物卡!CA30,人物卡!$DI$25:$DQ$29,1,FALSE),IFERROR(VLOOKUP(人物卡!CA30,人物卡!$CZ$25:$DB$29,1,FALSE),0))),"★",INDEX(本职技能!$A$2:$IC$87,MATCH(人物卡!CA30,本职技能!$A$2:$A$87,0),MATCH(人物卡!$BL$11,本职技能!$A$1:$IC$1,0))) -> 0 | CA30: 聆听 | CE30: 20 | CG30: =AR70 -> 0 | CM30: =SUM(CE30:CK30) -> 20 | CO30: =INT(CM30/2) -> 10 | CQ30: =INT(CM30/5) -> 4 | CT30: 请将你选择的任意特长写在上方栏内，这样既方便你写卡又方便KP审卡 | DT30: =附表!D75 -> 本次任务携带0.6美元
C31: - | F31: - | I31: - | L31: - | O31: - | R31: - | U31: - | X31: - | AA31: - | AD31: - | AG31: - | AJ31: - | AM31: - | AP31: - | AR31: =SUM(AO31,AL31,AI31,AF31,AC31,Z31,W31,T31,Q31,N31,K31,H31,E31,B31)-SUM(AQ31,AN31,AK31,AH31,AE31,AB31,Y31,V31,S31,P31,M31,J31,G31,D31) -> 0 | AT31: =AR31+BI31+BM31+BO31 -> 10 | AV31: =BE31 -> 博物学 | AY31: =BC31 -> 0 | BA31: ☐ | BC31: =IF(ISTEXT(IFERROR(VLOOKUP(人物卡!BE31,人物卡!$DI$25:$DQ$29,1,FALSE),IFERROR(VLOOKUP(人物卡!BE31,人物卡!$CZ$25:$DB$29,1,FALSE),0))),"★",INDEX(本职技能!$A$2:$IC$87,MATCH(人物卡!BE31,本职技能!$A$2:$A$87,0),MATCH(人物卡!$BL$11,本职技能!$A$1:$IC$1,0))) -> 0 | BE31: 博物学 | BI31: 10 | BK31: =AR31 -> 0 | BQ31: =SUM(BI31:BO31) -> 10 | BS31: =INT(BQ31/2) -> 5 | BU31: =INT(BQ31/5) -> 2 | BW31: ☐ | BY31: =IF(ISTEXT(IFERROR(VLOOKUP(人物卡!CA31,人物卡!$DI$25:$DQ$29,1,FALSE),IFERROR(VLOOKUP(人物卡!CA31,人物卡!$CZ$25:$DB$29,1,FALSE),0))),"★",INDEX(本职技能!$A$2:$IC$87,MATCH(人物卡!CA31,本职技能!$A$2:$A$87,0),MATCH(人物卡!$BL$11,本职技能!$A$1:$IC$1,0))) -> 0 | CA31: 侦查 | CE31: 25 | CG31: =AR71 -> 0 | CM31: =SUM(CE31:CK31) -> 25 | CO31: =INT(CM31/2) -> 12 | CQ31: =INT(CM31/5) -> 5 | CT31: 推 荐 关 系 人 | CU31: =IF(BL11=0," ",""&LOOKUP(BL11,职业列表!A2:A237,职业列表!K2:K237))
C32: - | F32: - | I32: - | L32: - | O32: - | R32: - | U32: - | X32: - | AA32: - | AD32: - | AG32: - | AJ32: - | AM32: - | AP32: - | AR32: =SUM(AO32,AL32,AI32,AF32,AC32,Z32,W32,T32,Q32,N32,K32,H32,E32,B32)-SUM(AQ32,AN32,AK32,AH32,AE32,AB32,Y32,V32,S32,P32,M32,J32,G32,D32) -> 0 | AT32: =AR32+BI32+BM32+BO32 -> 5 | AV32: =BE32 -> 神秘学 | AY32: =BC32 -> 0 | BA32: ☐ | BC32: =IF(ISTEXT(IFERROR(VLOOKUP(人物卡!BE32,人物卡!$DI$25:$DQ$29,1,FALSE),IFERROR(VLOOKUP(人物卡!BE32,人物卡!$CZ$25:$DB$29,1,FALSE),0))),"★",INDEX(本职技能!$A$2:$IC$87,MATCH(人物卡!BE32,本职技能!$A$2:$A$87,0),MATCH(人物卡!$BL$11,本职技能!$A$1:$IC$1,0))) -> 0 | BE32: 神秘学 | BI32: 5 | BK32: =AR32 -> 0 | BQ32: =SUM(BI32:BO32) -> 5 | BS32: =INT(BQ32/2) -> 2 | BU32: =INT(BQ32/5) -> 1 | BW32: ☐ | BY32: =IF(ISTEXT(IFERROR(VLOOKUP(人物卡!CA32,人物卡!$DI$25:$DQ$29,1,FALSE),IFERROR(VLOOKUP(人物卡!CA32,人物卡!$CZ$25:$DB$29,1,FALSE),0))),"★",INDEX(本职技能!$A$2:$IC$87,MATCH(人物卡!CA32,本职技能!$A$2:$A$87,0),MATCH(人物卡!$BL$11,本职技能!$A$1:$IC$1,0))) -> 0 | CA32: 追踪 | CE32: 10 | CG32: =AR72 -> 0 | CM32: =SUM(CE32:CK32) -> 10 | CO32: =INT(CM32/2) -> 5 | CQ32: =INT(CM32/5) -> 2
C33: - | F33: - | I33: - | L33: - | O33: - | R33: - | U33: - | X33: - | AA33: - | AD33: - | AG33: - | AJ33: - | AM33: - | AP33: - | AR33: =SUM(AO33,AL33,AI33,AF33,AC33,Z33,W33,T33,Q33,N33,K33,H33,E33,B33)-SUM(AQ33,AN33,AK33,AH33,AE33,AB33,Y33,V33,S33,P33,M33,J33,G33,D33) -> 0 | AT33: =AR33+BI33+BM33+BO33 -> 0 | AV33: =BE33 -> 信用评级 | AY33: =BC33 -> ★ | BA33: —— | BC33: ★ | BE33: 信用评级 | BI33: 0 | BK33: =AR33 -> 0 | BQ33: =SUM(BI33:BO33) -> 0 | BS33: =INT(BQ33/2) -> 0 | BU33: =INT(BQ33/5) -> 0 | BW33: ☐ | BY33: =IF(ISTEXT(IFERROR(VLOOKUP(人物卡!CA33,人物卡!$DI$25:$DQ$29,1,FALSE),IFERROR(VLOOKUP(人物卡!CA33,人物卡!$CZ$25:$DB$29,1,FALSE),0))),"★",INDEX(本职技能!$A$2:$IC$87,MATCH(人物卡!CA33,本职技能!$A$2:$A$87,0),MATCH(人物卡!$BL$11,本职技能!$A$1:$IC$1,0))) -> 0 | CA33: 导航 | CE33: 10 | CG33: =AR73 -> 0 | CM33: =SUM(CE33:CK33) -> 10 | CO33: =INT(CM33/2) -> 5 | CQ33: =INT(CM33/5) -> 2
C34: - | F34: - | I34: - | L34: - | O34: - | R34: - | U34: - | X34: - | AA34: - | AD34: - | AG34: - | AJ34: - | AM34: - | AP34: - | AR34: =SUM(AO34,AL34,AI34,AF34,AC34,Z34,W34,T34,Q34,N34,K34,H34,E34,B34)-SUM(AQ34,AN34,AK34,AH34,AE34,AB34,Y34,V34,S34,P34,M34,J34,G34,D34) -> 0 | AT34: =AR34+BI34 -> 0 | AV34: =BE34 -> 克苏鲁神话 | AY34: =BC34 -> 0 | BA34: —— | BC34: =IF(ISTEXT(IFERROR(VLOOKUP(人物卡!BE34,人物卡!$DI$25:$DQ$29,1,FALSE),IFERROR(VLOOKUP(人物卡!BE34,人物卡!$CZ$25:$DB$29,1,FALSE),0))),"★",INDEX(本职技能!$A$2:$IC$87,MATCH(人物卡!BE34,本职技能!$A$2:$A$87,0),MATCH(人物卡!$BL$11,本职技能!$A$1:$IC$1,0))) -> 0 | BE34: 克苏鲁神话 | BI34: 0 | BK34: =AR34 -> 0 | BM34: —— | BO34: —— | BQ34: =SUM(BI34:BO34) -> 0 | BS34: =INT(BQ34/2) -> 0 | BU34: =INT(BQ34/5) -> 0 | BW34: ☐ | BY34: =IF(ISTEXT(IFERROR(VLOOKUP(人物卡!CA34,人物卡!$DI$25:$DQ$29,1,FALSE),IFERROR(VLOOKUP(人物卡!CA34,人物卡!$CZ$25:$DB$29,1,FALSE),0))),"★",INDEX(本职技能!$A$2:$IC$87,MATCH(人物卡!CA34,本职技能!$A$2:$A$87,0),MATCH(人物卡!$BL$11,本职技能!$A$1:$IC$1,0))) -> 0 | CA34: 心理学 | CE34: 10 | CG34: =AR74 -> 0 | CM34: =SUM(CE34:CK34) -> 10 | CO34: =INT(CM34/2) -> 5 | CQ34: =INT(CM34/5) -> 2
C35: - | F35: - | I35: - | L35: - | O35: - | R35: - | U35: - | X35: - | AA35: - | AD35: - | AG35: - | AJ35: - | AM35: - | AP35: - | AR35: =SUM(AO35,AL35,AI35,AF35,AC35,Z35,W35,T35,Q35,N35,K35,H35,E35,B35)-SUM(AQ35,AN35,AK35,AH35,AE35,AB35,Y35,V35,S35,P35,M35,J35,G35,D35) -> 0 | AT35: =AR35+BI35+BM35+BO35 -> 10 | AV35: =BE35 -> 机械维修 | AY35: =BC35 -> 0 | BA35: ☐ | BC35: =IF(ISTEXT(IFERROR(VLOOKUP(人物卡!BE35,人物卡!$DI$25:$DQ$29,1,FALSE),IFERROR(VLOOKUP(人物卡!BE35,人物卡!$CZ$25:$DB$29,1,FALSE),0))),"★",INDEX(本职技能!$A$2:$IC$87,MATCH(人物卡!BE35,本职技能!$A$2:$A$87,0),MATCH(人物卡!$BL$11,本职技能!$A$1:$IC$1,0))) -> 0 | BE35: 机械维修 | BI35: 10 | BK35: =AR35 -> 0 | BQ35: =SUM(BI35:BO35) -> 10 | BS35: =INT(BQ35/2) -> 5 | BU35: =INT(BQ35/5) -> 2 | BW35: ☐ | BY35: =IF(ISTEXT(IFERROR(VLOOKUP(人物卡!CA35,人物卡!$DI$25:$DQ$29,1,FALSE),IFERROR(VLOOKUP(人物卡!CA35,人物卡!$CZ$25:$DB$29,1,FALSE),0))),"★",INDEX(本职技能!$A$2:$IC$87,MATCH(人物卡!CA35,本职技能!$A$2:$A$87,0),MATCH(人物卡!$BL$11,本职技能!$A$1:$IC$1,0))) -> 0 | CA35: 取悦 | CE35: 15 | CG35: =AR75 -> 0 | CM35: =SUM(CE35:CK35) -> 15 | CO35: =INT(CM35/2) -> 7 | CQ35: =INT(CM35/5) -> 3
C36: - | F36: - | I36: - | L36: - | O36: - | R36: - | U36: - | X36: - | AA36: - | AD36: - | AG36: - | AJ36: - | AM36: - | AP36: - | AR36: =SUM(AO36,AL36,AI36,AF36,AC36,Z36,W36,T36,Q36,N36,K36,H36,E36,B36)-SUM(AQ36,AN36,AK36,AH36,AE36,AB36,Y36,V36,S36,P36,M36,J36,G36,D36) -> 0 | AT36: =AR36+BI36+BM36+BO36 -> 10 | AV36: =BE36 -> 电气维修 | AY36: =BC36 -> 0 | BA36: ☐ | BC36: =IF(ISTEXT(IFERROR(VLOOKUP(人物卡!BE36,人物卡!$DI$25:$DQ$29,1,FALSE),IFERROR(VLOOKUP(人物卡!BE36,人物卡!$CZ$25:$DB$29,1,FALSE),0))),"★",INDEX(本职技能!$A$2:$IC$87,MATCH(人物卡!BE36,本职技能!$A$2:$A$87,0),MATCH(人物卡!$BL$11,本职技能!$A$1:$IC$1,0))) -> 0 | BE36: 电气维修 | BI36: 10 | BK36: =AR36 -> 0 | BQ36: =SUM(BI36:BO36) -> 10 | BS36: =INT(BQ36/2) -> 5 | BU36: =INT(BQ36/5) -> 2 | BW36: ☐ | BY36: =IF(ISTEXT(IFERROR(VLOOKUP(人物卡!CA36,人物卡!$DI$25:$DQ$29,1,FALSE),IFERROR(VLOOKUP(人物卡!CA36,人物卡!$CZ$25:$DB$29,1,FALSE),0))),"★",INDEX(本职技能!$A$2:$IC$87,MATCH(人物卡!CA36,本职技能!$A$2:$A$87,0),MATCH(人物卡!$BL$11,本职技能!$A$1:$IC$1,0))) -> 0 | CA36: 话术 | CE36: 5 | CG36: =AR76 -> 0 | CM36: =SUM(CE36:CK36) -> 5 | CO36: =INT(CM36/2) -> 2 | CQ36: =INT(CM36/5) -> 1 | CT36: 职业介绍
C37: - | F37: - | I37: - | L37: - | O37: - | R37: - | U37: - | X37: - | AA37: - | AD37: - | AG37: - | AJ37: - | AM37: - | AP37: - | AR37: =SUM(AO37,AL37,AI37,AF37,AC37,Z37,W37,T37,Q37,N37,K37,H37,E37,B37)-SUM(AQ37,AN37,AK37,AH37,AE37,AB37,Y37,V37,S37,P37,M37,J37,G37,D37) -> 0 | AT37: =AR37+BI37+BM37+BO37 -> 1 | AV37: =BE37 -> 电子学 Ω | AY37: =BC37 -> 0 | BA37: ☐ | BC37: =IF(ISTEXT(IFERROR(VLOOKUP(人物卡!BE37,人物卡!$DI$25:$DQ$29,1,FALSE),IFERROR(VLOOKUP(人物卡!BE37,人物卡!$CZ$25:$DB$29,1,FALSE),0))),"★",INDEX(本职技能!$A$2:$IC$87,MATCH(人物卡!BE37,本职技能!$A$2:$A$87,0),MATCH(人物卡!$BL$11,本职技能!$A$1:$IC$1,0))) -> 0 | BE37: 电子学 Ω | BI37: 1 | BK37: =AR37 -> 0 | BQ37: =SUM(BI37:BO37) -> 1 | BS37: =INT(BQ37/2) -> 0 | BU37: =INT(BQ37/5) -> 0 | BW37: ☐ | BY37: =IF(ISTEXT(IFERROR(VLOOKUP(人物卡!CA37,人物卡!$DI$25:$DQ$29,1,FALSE),IFERROR(VLOOKUP(人物卡!CA37,人物卡!$CZ$25:$DB$29,1,FALSE),0))),"★",INDEX(本职技能!$A$2:$IC$87,MATCH(人物卡!CA37,本职技能!$A$2:$A$87,0),MATCH(人物卡!$BL$11,本职技能!$A$1:$IC$1,0))) -> 0 | CA37: 恐吓 | CE37: 15 | CG37: =AR77 -> 0 | CM37: =SUM(CE37:CK37) -> 15 | CO37: =INT(CM37/2) -> 7 | CQ37: =INT(CM37/5) -> 3 | CT37: =IF(BL11=0," ",""&LOOKUP(BL11,职业列表!A2:A237,职业列表!M2:M237))
C38: - | F38: - | I38: - | L38: - | O38: - | R38: - | U38: - | X38: - | AA38: - | AD38: - | AG38: - | AJ38: - | AM38: - | AP38: - | AR38: =SUM(AO38,AL38,AI38,AF38,AC38,Z38,W38,T38,Q38,N38,K38,H38,E38,B38)-SUM(AQ38,AN38,AK38,AH38,AE38,AB38,Y38,V38,S38,P38,M38,J38,G38,D38) -> 0 | AT38: =AR38+BI38+BM38+BO38 -> 1 | AV38: =BE38 -> 操作重型机械 | AY38: =BC38 -> 0 | BA38: ☐ | BC38: =IF(ISTEXT(IFERROR(VLOOKUP(人物卡!BE38,人物卡!$DI$25:$DQ$29,1,FALSE),IFERROR(VLOOKUP(人物卡!BE38,人物卡!$CZ$25:$DB$29,1,FALSE),0))),"★",INDEX(本职技能!$A$2:$IC$87,MATCH(人物卡!BE38,本职技能!$A$2:$A$87,0),MATCH(人物卡!$BL$11,本职技能!$A$1:$IC$1,0))) -> 0 | BE38: 操作重型机械 | BI38: 1 | BK38: =AR38 -> 0 | BQ38: =SUM(BI38:BO38) -> 1 | BS38: =INT(BQ38/2) -> 0 | BU38: =INT(BQ38/5) -> 0 | BW38: ☐ | BY38: =IF(ISTEXT(IFERROR(VLOOKUP(人物卡!CA38,人物卡!$DI$25:$DQ$29,1,FALSE),IFERROR(VLOOKUP(人物卡!CA38,人物卡!$CZ$25:$DB$29,1,FALSE),0))),"★",INDEX(本职技能!$A$2:$IC$87,MATCH(人物卡!CA38,本职技能!$A$2:$A$87,0),MATCH(人物卡!$BL$11,本职技能!$A$1:$IC$1,0))) -> 0 | CA38: 说服 | CE38: 10 | CG38: =AR78 -> 0 | CM38: =SUM(CE38:CK38) -> 10 | CO38: =INT(CM38/2) -> 5 | CQ38: =INT(CM38/5) -> 2
C39: - | F39: - | I39: - | L39: - | O39: - | R39: - | U39: - | X39: - | AA39: - | AD39: - | AG39: - | AJ39: - | AM39: - | AP39: - | AR39: =SUM(AO39,AL39,AI39,AF39,AC39,Z39,W39,T39,Q39,N39,K39,H39,E39,B39)-SUM(AQ39,AN39,AK39,AH39,AE39,AB39,Y39,V39,S39,P39,M39,J39,G39,D39) -> 0 | AT39: =AR39+BI39+BM39+BO39 -> 1 | AV39: =BE39 -> 爆破 | AY39: =BC39 -> 0 | BA39: ☐ | BC39: =IF(ISTEXT(IFERROR(VLOOKUP(人物卡!BE39,人物卡!$DI$25:$DQ$29,1,FALSE),IFERROR(VLOOKUP(人物卡!BE39,人物卡!$CZ$25:$DB$29,1,FALSE),0))),"★",INDEX(本职技能!$A$2:$IC$87,MATCH(人物卡!BE39,本职技能!$A$2:$A$87,0),MATCH(人物卡!$BL$11,本职技能!$A$1:$IC$1,0))) -> 0 | BE39: 爆破 | BI39: 1 | BK39: =AR39 -> 0 | BQ39: =SUM(BI39:BO39) -> 1 | BS39: =INT(BQ39/2) -> 0 | BU39: =INT(BQ39/5) -> 0 | BW39: ☐ | BY39: =IF(ISTEXT(IFERROR(VLOOKUP(人物卡!CA39,人物卡!$DI$25:$DQ$29,1,FALSE),IFERROR(VLOOKUP(人物卡!CA39,人物卡!$CZ$25:$DB$29,1,FALSE),0))),"★",INDEX(本职技能!$A$2:$IC$87,MATCH(人物卡!CA39,本职技能!$A$2:$A$87,0),MATCH(人物卡!$BL$11,本职技能!$A$1:$IC$1,0))) -> 0 | CA39: 跳跃 | CE39: 20 | CG39: =AR79 -> 0 | CM39: =SUM(CE39:CK39) -> 20 | CO39: =INT(CM39/2) -> 10 | CQ39: =INT(CM39/5) -> 4
C40: - | F40: - | I40: - | L40: - | O40: - | R40: - | U40: - | X40: - | AA40: - | AD40: - | AG40: - | AJ40: - | AM40: - | AP40: - | AR40: =SUM(AO40,AL40,AI40,AF40,AC40,Z40,W40,T40,Q40,N40,K40,H40,E40,B40)-SUM(AQ40,AN40,AK40,AH40,AE40,AB40,Y40,V40,S40,P40,M40,J40,G40,D40) -> 0 | AT40: =IFERROR(AR40+BI40+BM40+BO40,"禁用") -> 禁用 | AV40: =BE40 -> 计算机使用 Ω | AY40: =BC40 -> 0 | BA40: ☐ | BC40: =IF(ISTEXT(IFERROR(VLOOKUP(人物卡!BE40,人物卡!$DI$25:$DQ$29,1,FALSE),IFERROR(VLOOKUP(人物卡!BE40,人物卡!$CZ$25:$DB$29,1,FALSE),0))),"★",INDEX(本职技能!$A$2:$IC$87,MATCH(人物卡!BE40,本职技能!$A$2:$A$87,0),MATCH(人物卡!$BL$11,本职技能!$A$1:$IC$1,0))) -> 0 | BE40: 计算机使用 Ω | BI40: =IF(BL10="1920s","禁用",5) -> 禁用 | BK40: =AR40 -> 0 | BQ40: =SUM(BI40:BO40) -> 0 | BS40: =INT(BQ40/2) -> 0 | BU40: =INT(BQ40/5) -> 0 | BW40: ☐ | BY40: =IF(ISTEXT(IFERROR(VLOOKUP(人物卡!CA40,人物卡!$DI$25:$DQ$29,1,FALSE),IFERROR(VLOOKUP(人物卡!CA40,人物卡!$CZ$25:$DB$29,1,FALSE),0))),"★",INDEX(本职技能!$A$2:$IC$87,MATCH(人物卡!CA40,本职技能!$A$2:$A$87,0),MATCH(人物卡!$BL$11,本职技能!$A$1:$IC$1,0))) -> 0 | CA40: 攀爬 | CE40: 20 | CG40: =AR80 -> 0 | CM40: =SUM(CE40:CK40) -> 20 | CO40: =INT(CM40/2) -> 10 | CQ40: =INT(CM40/5) -> 4
...

Sheet 附表
AJ1: 自定义职业属性
B2: 移动力计算 | S2: 自定义职业
A3: 护甲表减值 是否开启 | B3: 护甲表减值 | C3: 年龄减值 | D3: 力量-体型 | E3: =G14-I14 -> 0 | G3: 技能雷达表 | H3: 值 | I3: 总数 | J3: 百分比 | N3: 伤害加值与体格 | S3: 属性名称 | T3: shiyong | U3: 使用倍数 | V3: 计算
D4: 敏捷-体型 | E4: =J14-I14 -> 0 | G4: 调查 | H4: 交涉 | I4: 战斗 | J4: 特技 | K4: 支援 | L4: 学问 | N4: 力量+体型 | S4: ="力量×"&U4 -> 力量×0 | T4: =职业列表!I20 -> × | U4: =职业列表!J20 -> 0 | V4: =G14*U4 -> 0 | X4: =IF(U4>0,S4,"") | Y4: =IF(AND(U5>0,U4>0),"+","") | Z4: =IF(U5>0,S5,"") | AK4: 战斗 | AL4: ←请选择类型 | AM4: 爆破 | AN4: 电气维修 | AO4: 炮术 | AP4: 投掷 | AQ4: 格斗1 | AR4: 格斗2 | AS4: 格斗3 | AT4: 格斗4 | AU4: 格斗5 | AV4: 射击1 | AW4: 射击2 | AX4: 射击3 | AY4: 射击4 | AZ4: 射击5 | BC4: 斗殴 | BD4: 手枪 | BE4: 没有数值 | BF4: 最大值 | BG4: 最终出目
A5: =IF(人物卡!CH21="开",1,IF(人物卡!CH21="关",0)) -> 0 | B5: =IF(人物卡!CM21=0,"0",VLOOKUP(人物卡!CM21,'防具表 载具表'!B2:I101,3,FALSE)) -> 0 | C5: =IFERROR(0,IF(人物卡!BD12<40,0,INT((人物卡!BD12/10)-3))) -> 0 | D5: 力量大小 | E5: =IF(E3>0,"1",IF(E3=0,"0",IF(E3<0,"-1"))) -> 0 | G5: =AVERAGE(人物卡!BZ13+人物卡!BQ25+人物卡!BQ26+人物卡!BQ27+人物卡!BQ28+人物卡!BQ34+人物卡!BQ36+人物卡!BQ55+人物卡!BQ56+人物卡!BQ57+人物卡!CM26+人物卡!CM27+人物卡!CM31+人物卡!CM33+人物卡!CM37+人物卡!CM38+人物卡!CM44+人物卡!CM49+人物卡!CM53-122) -> 4 | H5: =AVERAGE(人物卡!BZ11+人物卡!BQ26+人物卡!BQ27+人物卡!BQ32+人物卡!BQ35+人物卡!BQ37+人物卡!BQ42+人物卡!BQ53+人物卡!BQ55+人物卡!BQ56+人物卡!BQ57+人物卡!BQ58+人物卡!CM25+人物卡!CM35+人物卡!CM37+人物卡!CM38+人物卡!CM44+人物卡!CM49+人物卡!CM53-111-人物卡!BI58) -> -17 | I5: =AVERAGE((人物卡!BT9+人物卡!BT13)/2+人物卡!BT11+人物卡!BZ9+人物卡!BQ38+人物卡!BQ43+人物卡!BQ44+人物卡!BQ45+人物卡!BQ47+人物卡!BQ48+人物卡!BQ49+人物卡!BQ53+人物卡!BQ54+人物卡!CM27+人物卡!CM34+人物卡!CM38+人物卡!CM39+人物卡!CM44+人物卡!CM45+人物卡!CM48+人物卡!CM50+人物卡!CM52+人物卡!CM54+人物卡!CM55-189-人物卡!BI38) -> -108 | J5: =AVERAGE(人物卡!BZ9+人物卡!BQ28+人物卡!BQ29+人物卡!BQ30+人物卡!BQ31+人物卡!BQ33+人物卡!BQ37+人物卡!BQ39+人物卡!BQ40+人物卡!BQ54+人物卡!CM28+人物卡!CM29+人物卡!CM30+人物卡!CM32+人物卡!CM34+人物卡!CM36+人物卡!CM39+人物卡!CM43+人物卡!CM45+人物卡!CM46+人物卡!CM47+人物卡!CM48+人物卡!CM49+人物卡!CM50+人物卡!CM51+人物卡!CM52+人物卡!CM54+人物卡!CM55-219) -> -8 | K5: =AVERAGE(人物卡!BQ51+人物卡!CM30+人物卡!CM37+人物卡!BQ39+人物卡!CM36+人物卡!CM39+人物卡!CM32+人物卡!BQ35+人物卡!BQ26+人物卡!CM50+人物卡!CM54+人物卡!CM55-76) -> 22 | L5: =AVERAGE(人物卡!CF11+人物卡!BZ13+人物卡!BQ25+人物卡!BQ26+人物卡!BQ34+人物卡!BQ36+人物卡!BQ41+人物卡!BQ52+人物卡!BQ55+人物卡!BQ56+人物卡!BQ57+人物卡!BQ58-人物卡!BI58+人物卡!CM25+人物卡!CM26+人物卡!CM30+人物卡!CM31+人物卡!CM33+人物卡!CM37+人物卡!CM38+人物卡!CM40+人物卡!CM41+人物卡!CM42+人物卡!CM53-76) -> 75 | N5: =IFERROR(G14+I14,0) -> 0 | S5: ="敏捷×"&U5 -> 敏捷×0 | T5: =职业列表!I21 -> × | U5: =职业列表!J21 -> 0 | V5: =J14*U5 -> 0 | X5: =IF(U5>0,S5,"") | Y5: =IF(AND(U6>0,U5>0),"+","") | AL5: =IF(人物卡!BK69=AL4,"") | AM5: =IF(人物卡!BK69=Blasting,blast) -> FALSE | AN5: =IF(人物卡!BK69=memaing,mema) -> FALSE | AO5: =IF(人物卡!BK69=arting,arti) -> FALSE | AP5: =IF(人物卡!BK69=throwing,throw) -> FALSE | AQ5: =IF(人物卡!BK69=dbog,dbo) -> FALSE | AR5: =IF(人物卡!BK69=dbtg,dbt) -> FALSE | AS5: =IF(人物卡!BK69=dbthg,dbth) -> FALSE | AT5: =IF(人物卡!BK69=dbfg,dbf) -> FALSE | AU5: =IF(人物卡!BK69=dbfig,dbfi) -> FALSE | AV5: =IF(人物卡!BK69=shog,sho) -> FALSE | AW5: =IF(人物卡!BK69=shtg,sht) -> FALSE | AX5: =IF(人物卡!BK69=shthg,shth) -> FALSE | AY5: =IF(人物卡!BK69=shfg,shf) -> FALSE | AZ5: =IF(人物卡!BK69=shfig,shfi) -> FALSE | BC5: =IF(人物卡!BK69=fighting,fight) -> FALSE | BD5: =IF(人物卡!BK69=pistoling,pistol) -> FALSE | BE5: =IF(BF5=0,IF(人物卡!BK69=附表!U227,附表!V227,IF(人物卡!BK69=附表!U220,附表!V220,IF(人物卡!BK69=附表!U221,附表!V221,IF(人物卡!BK69=附表!U219,附表!V219,IF(人物卡!BK69=附表!U224,附表!V224,IF(人物卡!BK69=附表!U225,附表!V225,IF(人物卡!BK69=附表!U223,附表!V223,IF(人物卡!BK69=附表!U222,附表!V222,IF(人物卡!BK69=附表!U226,技能注释!#REF!,IF(人物卡!BK69=附表!Q220,附表!R220,IF(人物卡!BK69=附表!Q221,附表!R221,IF(人物卡!BK69=附表!Q222,附表!R222,IF(人物卡!BK69=附表!Q223,附表!R223,IF(人物卡!BK69=附表!Q224,附表!R224,IF(人物卡!BK69=附表!Q219,附表!R219,IF(人物卡!BK69=附表!Q225,附表!R225,""))))))))))))))))) | BF5: =MAX(AL5:BD5) -> 0 | BG5: =IF(BF5=0,BE5,BF5)
B6: 检测是否为数字 | C6: 最终年龄减值 | D6: 敏捷大小 | E6: =IF(E4>0,"1",IF(E4=0,"0",IF(E4<0,"-1"))) -> 0 | J6: =G5+H5+I5+J5+K5+L5 -> -32 | N6: 非八十整数体格 | O6: 减485后八十的倍数 | P6: 最终体格出目 | S6: ="体质×"&U6 -> 体质×0 | T6: =职业列表!I22 -> × | U6: =职业列表!J22 -> 0 | V6: =H14*U6 -> 0 | X6: =IF(U6>0,S6,"") | Y6: =IF(AND(U7>0,U6>0),"+","") | AL6: =IF(人物卡!BK70=$AL$4,"") -> FALSE | AM6: =IF(人物卡!BK70=AM4,blast) -> FALSE | AN6: =IF(人物卡!BK70=AN4,mema) -> FALSE | AO6: =IF(人物卡!BK70=AO4,arti) -> FALSE | AP6: =IF(人物卡!BK70=AP4,throw) -> FALSE | AQ6: =IF(ISBLANK(dbog),FALSE,IF(人物卡!BK70=dbog,dbo)) -> FALSE | AR6: =IF(ISBLANK(dbt),FALSE,IF(人物卡!BK70=dbtg,dbt)) -> 0 | AS6: =IF(ISBLANK(dbth),FALSE,IF(人物卡!BK70=dbthg,dbth)) -> 0 | AT6: =IF(人物卡!BK70=dbfg,dbf) -> 0 | AU6: =IF(人物卡!BK70=dbfig,dbfi) -> 0 | AV6: =IF(ISBLANK(shog),FALSE,IF(人物卡!BK70=shog,sho)) -> FALSE | AW6: =IF(ISBLANK(shtg),FALSE,IF(人物卡!BK70=shtg,sht)) -> FALSE | AX6: =IF(ISBLANK(shthg),FALSE,IF(人物卡!BK70=shthg,shth)) -> FALSE | AY6: =IF(人物卡!BK70=shfg,shf) -> 0 | AZ6: =IF(人物卡!BK70=shfig,shfi) -> 0 | BC6: =IF(人物卡!BK70=BC4,fight) -> FALSE | BD6: =IF(人物卡!BK70=BD4,pistol) -> FALSE | BE6: =IF(BF6=0,IF(人物卡!BK70=附表!U227,附表!V227,IF(人物卡!BK70=附表!U220,附表!V220,IF(人物卡!BK70=附表!U221,附表!V221,IF(人物卡!BK70=附表!U219,附表!V219,IF(人物卡!BK70=附表!U224,附表!V224,IF(人物卡!BK70=附表!U225,附表!V225,IF(人物卡!BK70=附表!U223,附表!V223,IF(人物卡!BK70=附表!U222,附表!V222,IF(人物卡!BK70=附表!U226,技能注释!#REF!,IF(人物卡!BK70=附表!Q220,附表!R220,IF(人物卡!BK70=附表!Q221,附表!R221,IF(人物卡!BK70=附表!Q222,附表!R222,IF(人物卡!BK70=附表!Q223,附表!R223,IF(人物卡!BK70=附表!Q224,附表!R224,IF(人物卡!BK70=附表!Q219,附表!R219,IF(人物卡!BK70=附表!Q225,附表!R225,""))))))))))))))))) | BF6: =MAX(AL6:BD6) -> 0 | BG6: =IF(BF6=0,BE6,BF6)
B7: =ISNUMBER(B5) -> TRUE | C7: =IF(ISBLANK(人物卡!BD12),0,IF(人物卡!BD12>=0,C5,0)) -> 0 | D7: 总值 | E7: =E6+E5 -> 0 | G7: 调查 | H7: 交涉 | I7: 战斗 | J7: 特技 | K7: 支援 | L7: 学问 | N7: =IF(N5<=1,"0",IF(N5<=64,"-2",IF(N5<=84,"-1",IF(N5<=124,"0",IF(N5<=164,"1",IF(N5<=204,"2",IF(N5<=284,"3",IF(N5>284,"4","0")))))))) -> 0 | O7: =INT((N5-285)/80) -> -4 | P7: =IF(O7>=0,O7+N7,N7) -> 0 | S7: ="体型×"&U7 -> 体型×0 | T7: =职业列表!I23 -> × | U7: =职业列表!J23 -> 0 | V7: =I14*U7 -> 0 | X7: =IF(U7>0,S7,"") | Y7: =IF(AND(U8>0,U7>0),"+","") | AL7: =IF(人物卡!BK71=$AL$4,"") -> FALSE | AM7: =IF(人物卡!BK71=$AM$4,blast) -> FALSE | AN7: =IF(人物卡!BK71=$AN$4,mema) -> FALSE | AO7: =IF(人物卡!BK71=$AO$4,arti) -> FALSE | AP7: =IF(人物卡!BK71=$AP$4,throw) -> FALSE | AQ7: =IF(ISBLANK(dbog),FALSE,IF(人物卡!BK71=dbog,dbo)) -> FALSE | AR7: =IF(ISBLANK(dbt),FALSE,IF(人物卡!BK71=dbtg,dbt)) -> 0 | AS7: =IF(ISBLANK(dbth),FALSE,IF(人物卡!BK71=dbthg,dbth)) -> 0 | AT7: =IF(人物卡!BK71=dbfg,dbf) -> 0 | AU7: =IF(人物卡!BK71=dbfig,dbfi) -> 0 | AV7: =IF(ISBLANK(shog),FALSE,IF(人物卡!BK71=shog,sho)) -> FALSE | AW7: =IF(ISBLANK(shtg),FALSE,IF(人物卡!BK71=shtg,sht)) -> FALSE | AX7: =IF(ISBLANK(shthg),FALSE,IF(人物卡!BK71=shthg,shth)) -> FALSE | AY7: =IF(人物卡!BK71=shfg,shf) -> 0 | AZ7: =IF(人物卡!BK71=shfig,shfi) -> 0 | BC7: =IF(人物卡!BK71=$BC$4,fight) -> FALSE | BD7: =IF(人物卡!BK71=$BD$4,pistol) -> FALSE | BE7: =IF(BF7=0,IF(人物卡!BK71=附表!U227,附表!V227,IF(人物卡!BK71=附表!U220,附表!V220,IF(人物卡!BK71=附表!U221,附表!V221,IF(人物卡!BK71=附表!U219,附表!V219,IF(人物卡!BK71=附表!U224,附表!V224,IF(人物卡!BK71=附表!U225,附表!V225,IF(人物卡!BK71=附表!U223,附表!V223,IF(人物卡!BK71=附表!U222,附表!V222,IF(人物卡!BK71=附表!U226,技能注释!#REF!,IF(人物卡!BK71=附表!Q220,附表!R220,IF(人物卡!BK71=附表!Q221,附表!R221,IF(人物卡!BK71=附表!Q222,附表!R222,IF(人物卡!BK71=附表!Q223,附表!R223,IF(人物卡!BK71=附表!Q224,附表!R224,IF(人物卡!BK71=附表!Q219,附表!R219,IF(人物卡!BK71=附表!Q225,附表!R225,""))))))))))))))))) | BF7: =MAX(AL7:BD7) -> 0 | BG7: =IF(BF7=0,BE7,BF7)
B8: 护甲表最终减值 | C8: =IF(B7=FALSE,"0",IF(A5=1,B5,0)) -> 0 | D8: 属性最终值 | E8: =IF(E7=2,"1",IF(E7=-2,"-1",0)) -> 0 | G8: =G5/J6 -> -0.125 | H8: =H5/J6 -> 0.53125 | I8: =I5/J6 -> 3.375 | J8: =J5/J6 -> 0.25 | K8: =K5/J6 -> -0.6875 | L8: =L5/J6 -> -2.34375 | N8: 小于1D6的话 | O8: 超过1d6的话 | P8: 最终伤害加值出目 | S8: ="外貌×"&U8 -> 外貌×0 | T8: =职业列表!I24 -> × | U8: =职业列表!J24 -> 0 | V8: =K14*U8 -> 0 | X8: =IF(U8>0,S8,"") | Y8: =IF(AND(U9>0,U8>0),"+","") | AL8: =IF(人物卡!BK72=$AL$4,"") -> FALSE | AM8: =IF(人物卡!BK72=$AM$4,blast) -> FALSE | AN8: =IF(人物卡!BK72=$AN$4,mema) -> FALSE | AO8: =IF(人物卡!BK72=$AO$4,arti) -> FALSE | AP8: =IF(人物卡!BK72=$AP$4,throw) -> FALSE | AQ8: =IF(ISBLANK(dbog),FALSE,IF(人物卡!BK72=dbog,dbo)) -> FALSE | AR8: =IF(ISBLANK(dbt),FALSE,IF(人物卡!BK72=dbtg,dbt)) -> 0 | AS8: =IF(ISBLANK(dbth),FALSE,IF(人物卡!BK72=dbthg,dbth)) -> 0 | AT8: =IF(人物卡!BK72=dbfg,dbf) -> 0 | AU8: =IF(人物卡!BK72=dbfig,dbfi) -> 0 | AV8: =IF(ISBLANK(shog),FALSE,IF(人物卡!BK72=shog,sho)) -> FALSE | AW8: =IF(ISBLANK(shtg),FALSE,IF(人物卡!BK72=shtg,sht)) -> FALSE | AX8: =IF(ISBLANK(shthg),FALSE,IF(人物卡!BK72=shthg,shth)) -> FALSE | AY8: =IF(人物卡!BK72=shfg,shf) -> 0 | AZ8: =IF(人物卡!BK72=shfig,shfi) -> 0 | BC8: =IF(人物卡!BK72=$BC$4,fight) -> FALSE | BD8: =IF(人物卡!BK72=$BD$4,pistol) -> FALSE | BE8: =IF(BF8=0,IF(人物卡!BK72=附表!U227,附表!V227,IF(人物卡!BK72=附表!U220,附表!V220,IF(人物卡!BK72=附表!U221,附表!V221,IF(人物卡!BK72=附表!U219,附表!V219,IF(人物卡!BK72=附表!U224,附表!V224,IF(人物卡!BK72=附表!U225,附表!V225,IF(人物卡!BK72=附表!U223,附表!V223,IF(人物卡!BK72=附表!U222,附表!V222,IF(人物卡!BK72=附表!U226,技能注释!#REF!,IF(人物卡!BK72=附表!Q220,附表!R220,IF(人物卡!BK72=附表!Q221,附表!R221,IF(人物卡!BK72=附表!Q222,附表!R222,IF(人物卡!BK72=附表!Q223,附表!R223,IF(人物卡!BK72=附表!Q224,附表!R224,IF(人物卡!BK72=附表!Q219,附表!R219,IF(人物卡!BK72=附表!Q225,附表!R225,""))))))))))))))))) | BF8: =MAX(AL8:BD8) -> 0 | BG8: =IF(BF8=0,BE8,BF8)
B9: 最终补正值 | C9: =E8-C8-C7 -> 0 | N9: =IF(P7="-2","-2",IF(P7="-1","-1",IF(P7="0","0",IF(P7="1","+1D4",IF(P7=2,"+1D6",IF(P7>2,"D6",0)))))) -> 0 | O9: =IF(N9="D6",P7-1,"0") -> 0 | P9: =IF(N9="D6",O10,N9) -> 0 | S9: ="智力×"&U9 -> 智力×0 | T9: =职业列表!I25 -> × | U9: =职业列表!J25 -> 0 | V9: =L14*U9 -> 0 | X9: =IF(U9>0,S9,"") | Y9: =IF(AND(U10>0,U9>0),"+","") | AA9: =X4&Y4&X5&Y5&X6&Y6&X7&Y7&X8&Y8&X9&Y9&X10&Y10&X11&Y11&X12 | AF9: 最终值 | AL9: =IF(人物卡!BK73=$AL$4,"") -> FALSE | AM9: =IF(人物卡!BK73=$AM$4,blast) -> FALSE | AN9: =IF(人物卡!BK73=$AN$4,mema) -> FALSE | AO9: =IF(人物卡!BK73=$AO$4,arti) -> FALSE | AP9: =IF(人物卡!BK73=$AP$4,throw) -> FALSE | AQ9: =IF(ISBLANK(dbog),FALSE,IF(人物卡!BK73=dbog,dbo)) -> FALSE | AR9: =IF(ISBLANK(dbt),FALSE,IF(人物卡!BK73=dbtg,dbt)) -> 0 | AS9: =IF(ISBLANK(dbth),FALSE,IF(人物卡!BK73=dbthg,dbth)) -> 0 | AT9: =IF(人物卡!BK73=dbfg,dbf) -> 0 | AU9: =IF(人物卡!BK73=dbfig,dbfi) -> 0 | AV9: =IF(ISBLANK(shog),FALSE,IF(人物卡!BK73=shog,sho)) -> FALSE | AW9: =IF(ISBLANK(shtg),FALSE,IF(人物卡!BK73=shtg,sht)) -> FALSE | AX9: =IF(ISBLANK(shthg),FALSE,IF(人物卡!BK73=shthg,shth)) -> FALSE | AY9: =IF(人物卡!BK73=shfg,shf) -> 0 | AZ9: =IF(人物卡!BK73=shfig,shfi) -> 0 | BC9: =IF(人物卡!BK73=$BC$4,fight) -> FALSE | BD9: =IF(人物卡!BK73=$BD$4,pistol) -> FALSE | BE9: =IF(BF9=0,IF(人物卡!BK73=附表!U227,附表!V227,IF(人物卡!BK73=附表!U220,附表!V220,IF(人物卡!BK73=附表!U221,附表!V221,IF(人物卡!BK73=附表!U219,附表!V219,IF(人物卡!BK73=附表!U224,附表!V224,IF(人物卡!BK73=附表!U225,附表!V225,IF(人物卡!BK73=附表!U223,附表!V223,IF(人物卡!BK73=附表!U222,附表!V222,IF(人物卡!BK73=附表!U226,技能注释!#REF!,IF(人物卡!BK73=附表!Q220,附表!R220,IF(人物卡!BK73=附表!Q221,附表!R221,IF(人物卡!BK73=附表!Q222,附表!R222,IF(人物卡!BK73=附表!Q223,附表!R223,IF(人物卡!BK73=附表!Q224,附表!R224,IF(人物卡!BK73=附表!Q219,附表!R219,IF(人物卡!BK73=附表!Q225,附表!R225,""))))))))))))))))) | BF9: =MAX(AL9:BD9) -> 0 | BG9: =IF(BF9=0,BE9,BF9)
O10: ="+"&O9&"D6" -> +0D6 | S10: ="教育×"&U10 -> 教育×0 | T10: =职业列表!I26 -> × | U10: =职业列表!J26 -> 0 | V10: =N14*U10 -> 0 | X10: =IF(U10>0,S10,"") | Y10: =IF(AND(U11>0,U10>0),"+","") | AA10: =IF(AB10=职业列表!H30,1,0) -> 0 | AB10: 教育+其他属性点数中的最大值（官方） | AF10: =IF(AA10=1,MAX(V4:V9,V11:V12)+V10,0) -> 0
S11: ="意志×"&U11 -> 意志×0 | T11: =职业列表!I27 -> × | U11: =职业列表!J27 -> 0 | V11: =M14*U11 -> 0 | X11: =IF(U11>0,S11,"") | Y11: =IF(AND(U12>0,U11>0),"+","") | AA11: =IF(AB11=职业列表!H30,1,0) -> 0 | AB11: 教育+其他属性点数中的所有值 | AF11: =IF(AA11=1,V10+SUM(V4:V9,V11:V12),0) -> 0
G12: 属性雷达表 | H12: 基础属性 | I12: 出目 | S12: ="幸运×"&U12 -> 幸运×0 | T12: =职业列表!I28 -> × | U12: =职业列表!J28 -> 0 | V12: =O14*U12 -> 0 | X12: =IF(U12>0,S12,"") | AA12: =IF(AB12=职业列表!H30,1,0) -> 1 | AB12: 所有属性的点数相加 | AF12: =IF(AA12=1,SUM(V4:V12),0) -> 0
G13: 力量 STR | H13: 体质 CON | I13: 体型 SIZ | J13: 敏捷 DEX | K13: 外貌 APP | L13: 智力 灵感 | M13: 意志 POW | N13: 教育 EDU | O13: 幸运 Luck | Y13: 格斗射击基础成功率
B14: 熟练下拉 | G14: =IF(STRA="未填写",0,STRA) -> 0 | H14: =IF(CONA="未填写",0,CONA) -> 0 | I14: =IF(SIZA="未填写",0,SIZA) -> 0 | J14: =IF(DEXA="未填写",0,) -> 0 | K14: =IF(APPA="未填写",0,) -> 0 | L14: =IF(INTA="未填写",0,) -> 0 | M14: =IF(POWA="未填写",0,) -> 0 | N14: =IF(EDUA="未填写",0,) -> 0 | O14: =IF(LuckA="未填写",0,) -> 0 | U14: 自定义技能剩余计算 | Y14: 格斗1 | Z14: =IF(人物卡!BG60="武术",1,IF(人物卡!BG60="鞭子","5",IF(人物卡!BG60="电锯","10",IF(人物卡!BG60="斧","15",IF(人物卡!BG60="剑","20",IF(人物卡!BG60="绞具","15",IF(人物卡!BG60="链枷","10",IF(人物卡!BG60="矛","20",IF(人物卡!BG60=人物卡!$X$110,人物卡!$AD$110,0))))))))) -> 0 | AA14: 射击1 | AB14: =IF(人物卡!CC60="步枪/霰弹枪","25",IF(人物卡!CC60="冲锋枪","15",IF(人物卡!CC60="弓术","15",IF(人物卡!CC60="喷射器","10",IF(人物卡!CC60="机枪","10",IF(人物卡!CC60="重武器","10",IF(人物卡!CC60=人物卡!$X$112,人物卡!$AD$112,0))))))) -> 0 | AZ14: 出目 | BA14: =IF(AX27="仅显示1890_2023","",VLOOKUP(AX27,AZ25:BB29,3,FALSE)) -> #N/A | BF14: 国家数 | BG14: 第一行政区 | BH14: 国家
B15: ★ | O15: 随身物品下拉表 | U15: 1 | V15: =人物卡!BG48 -> 0 | W15: =IF(V15="步枪/霰弹枪",1,0) -> 0 | Y15: 格斗2 | Z15: =IF(人物卡!BG61="武术",1,IF(人物卡!BG61="鞭子","5",IF(人物卡!BG61="电锯","10",IF(人物卡!BG61="斧","15",IF(人物卡!BG61="剑","20",IF(人物卡!BG61="绞具","15",IF(人物卡!BG61="链枷","10",IF(人物卡!BG61="矛","20",IF(人物卡!BG61=人物卡!$X$110,人物卡!$AD$110,0))))))))) -> 0 | AA15: 射击2 | AB15: =IF(人物卡!CC61="步枪/霰弹枪","25",IF(人物卡!CC61="冲锋枪","15",IF(人物卡!CC61="弓术","15",IF(人物卡!CC61="喷射器","10",IF(人物卡!CC61="机枪","10",IF(人物卡!CC61="重武器","10",IF(人物卡!CC61=人物卡!$X$112,人物卡!$AD$112,0))))))) -> 0 | BF15: =COUNTA(BH17:BH21,BH24:BH34,BH37:BH43,BH46:BH64,BH67:BH71,BH75:BH80,BH83:BH89,BH92:BH99,BH102:BH117,BH120:BH127,BH131:BH137,BH140:BH149,BH152:BH167,BH170:BH177,BH180:BH192,BH195:BH207,BH210:BH224) -> 174 | BG15: =COUNTA(BI17:EO224) -> 2834 | BH15: ——亚洲——
L16: san值计算 | O16: 颅———— | U16: 2 | V16: =人物卡!BG49 -> 0 | W16: =IF(V16="步枪/霰弹枪",1,0) -> 0 | Y16: 格斗3 | Z16: =IF(人物卡!BG62="武术",1,IF(人物卡!BG62="鞭子","5",IF(人物卡!BG62="电锯","10",IF(人物卡!BG62="斧","15",IF(人物卡!BG62="剑","20",IF(人物卡!BG62="绞具","15",IF(人物卡!BG62="链枷","10",IF(人物卡!BG62="矛","20",IF(人物卡!BG62=人物卡!$X$110,人物卡!$AD$110,0))))))))) -> 0 | AA16: 射击3 | AB16: =IF(人物卡!CC62="步枪/霰弹枪","25",IF(人物卡!CC62="冲锋枪","15",IF(人物卡!CC62="弓术","15",IF(人物卡!CC62="喷射器","10",IF(人物卡!CC62="机枪","10",IF(人物卡!CC62="重武器","10",IF(人物卡!CC62=人物卡!$X$112,人物卡!$AD$112,0))))))) -> 0 | BH16: *东亚*
L17: 意志 | M17: 最大值 | O17: 头部 | R17: 健康 | S17: 清醒 | U17: 3 | V17: =人物卡!BG50 -> 0 | W17: =IF(V17="步枪/霰弹枪",1,0) -> 0 | Y17: 格斗4 | Z17: =IF(人物卡!BG63="武术",1,IF(人物卡!BG63="鞭子","5",IF(人物卡!BG63="电锯","10",IF(人物卡!BG63="斧","15",IF(人物卡!BG63="剑","20",IF(人物卡!BG63="绞具","15",IF(人物卡!BG63="链枷","10",IF(人物卡!BG63="矛","20",IF(人物卡!BG63=人物卡!$X$110,人物卡!$AD$110,0))))))))) -> 0 | AA17: 射击4 | AB17: =IF(人物卡!CC63="步枪/霰弹枪","25",IF(人物卡!CC63="冲锋枪","15",IF(人物卡!CC63="弓术","15",IF(人物卡!CC63="喷射器","10",IF(人物卡!CC63="机枪","10",IF(人物卡!CC63="重武器","10",IF(人物卡!CC63=人物卡!$X$112,人物卡!$AD$112,0))))))) -> 0 | BH17: 中国 | BI17: 北京市* | BJ17: 天津市 | BK17: 河北省 | BL17: 山西省 | BM17: 内蒙古自治区 | BN17: 辽宁省 | BO17: 吉林省 | BP17: 黑龙江省 | BQ17: 上海市 | BR17: 江苏省 | BS17: 浙江省 | BT17: 安徽省 | BU17: 福建省 | BV17: 江西省 | BW17: 山东省 | BX17: 河南省 | BY17: 湖北省 | BZ17: 湖南省 | CA17: 广东省 | CB17: 广西壮族自治区 | CC17: 海南省 | CD17: 重庆市 | CE17: 四川省 | CF17: 贵州省 | CG17: 云南省 | CH17: 西藏自治区 | CI17: 陕西省 | CJ17: 甘肃省 | CK17: 青海省 | CL17: 宁夏回族自治区 | CM17: 新疆维吾尔自治区 | CN17: 台湾省 | CO17: 香港特别行政区 | CP17: 澳门特别行政区
B18: 可选规则：有故事的调查员 | L18: =M14 -> 0 | M18: =人物卡!BO19 -> 99 | O18: 头发 | R18: 昏迷 | S18: 临时疯狂 | U18: 自定义 | V18: =人物卡!CA57 -> 炮术 | W18: =IF(V18="自定义技能",1,0) -> 0 | Y18: 格斗5 | Z18: =IF(人物卡!BG64="武术",1,IF(人物卡!BG64="鞭子","5",IF(人物卡!BG64="电锯","10",IF(人物卡!BG64="斧","15",IF(人物卡!BG64="剑","20",IF(人物卡!BG64="绞具","15",IF(人物卡!BG64="链枷","10",IF(人物卡!BG64="矛","20",IF(人物卡!BG64=人物卡!$X$110,人物卡!$AD$110,0))))))))) -> 0 | AA18: 射击5 | AB18: =IF(人物卡!CC64="步枪/霰弹枪","25",IF(人物卡!CC64="冲锋枪","15",IF(人物卡!CC64="弓术","15",IF(人物卡!CC64="喷射器","10",IF(人物卡!CC64="机枪","10",IF(人物卡!CC64="重武器","10",IF(人物卡!CC64=人物卡!$X$112,人物卡!$AD$112,0))))))) -> 0 | BH18: 日本 | BI18: 东京都 | BJ18: 北海道 | BK18: 大阪府 | BL18: 京都府* | BM18: 青森县 | BN18: 岩手县 | BO18: 宫城县 | BP18: 秋田县 | BQ18: 山形县 | BR18: 福岛县 | BS18: 茨城县 | BT18: 栃木县 | BU18: 群马县 | BV18: 埼玉县 | BW18: 千叶县 | BX18: 神奈川县 | BY18: 新潟县 | BZ18: 富山县 | CA18: 石川县 | CB18: 福井县 | CC18: 山梨县 | CD18: 长野县 | CE18: 岐阜县 | CF18: 静冈县 | CG18: 爱知县 | CH18: 三重县 | CI18: 滋贺县 | CJ18: 兵库县 | CK18: 奈良县 | CL18: 和歌山县 | CM18: 鸟取县 | CN18: 岛根县 | CO18: 冈山县 | CP18: 山口县 | CQ18: 徳岛县 | CR18: 香川县 | CS18: 爱媛县 | CT18: 高知县 | CU18: 福冈县 | CV18: 佐贺县 | CW18: 长崎县 | CX18: 熊本县 | CY18: 大分县 | CZ18: 宫崎县 | DA18: 鹿儿岛县 | DB18: 冲绳县 | DC18: 广岛县
B19: 名称 | C19: san | D19: 技能 | E19: 备注 | L19: 最终值 | O19: 耳朵 | R19: 重伤 | S19: 不定性疯狂 | BH19: 韩国 | BI19: 首尔* | BJ19: 釜山 | BK19: 大邱 | BL19: 仁川 | BM19: 光州 | BN19: 大田 | BO19: 蔚山 | BP19: 世宗 | BQ19: 京畿道 | BR19: 江原道 | BS19: 忠北 | BT19: 忠南 | BU19: 全北 | BV19: 全南 | BW19: 庆北 | BX19: 庆南
B20: 战场经历包 | C20: 1d10+5 | D20: 70 | E20: 对目击尸体和重伤员造成的理智损失免疫;根据战争的年份和模组发生时的年份调整年龄；背景增加一项：战争相关的伤疤 / 疤痕或恐惧症 / 躁狂症 | L20: =IF(L18>M18,M18,L18) -> 0 | O20: 面部 | R20: 死亡 | S20: 永久疯狂 | AA20: 任意 | AR20: 特定时间 | BH20: 朝鲜 | BI20: 平壤* | BJ20: 平安南道 | BK20: 平安北道 | BL20: 慈江道 | BM20: 两江道 | BN20: 咸镜南道 | BO20: 咸镜北道 | BP20: 黄海北道 | BQ20: 黄海南道 | BR20: 江原道
B21: 警务经历包 | C21: 1d10 | D21: 60 | E21: 对目击尸体造成的理智损失免疫;初始年龄不能低于 25 岁;背景增加一项：警察工作相关的伤疤 / 疤痕或恐惧症 / 躁狂症； | O21: 颈部 | R21: =IF(ISBLANK(人物卡!X122),"",人物卡!X122) | S21: =IF(ISBLANK(人物卡!AB122),"",人物卡!AB122) | AA21: =IF(ISBLANK(人物卡!CZ25),0,1) -> 0 | AB21: =IF(ISBLANK(人物卡!DI25),0,1) -> 0 | AC21: 已用总数 | AD21: 是否停用 | AE21: 最终值 | AR21: =人物卡!DK93 -> 1924 | AS21: =IF(AR21="仅显示1890_2023","",VLOOKUP(AR21,AE33:AS166,15,FALSE)) -> 纸制鸡蛋托 面巾纸 | BH21: 蒙古 | BI21: 乌兰巴托市* | BJ21: 后杭爱省 | BK21: 巴彦乌勒盖省 | BL21: 巴彦洪格尔省 | BM21: 布尔干省 | BN21: 戈壁阿尔泰省 | BO21: 东戈壁省 | BP21: 东方省 | BQ21: 中戈壁省 | BR21: 扎布汗省 | BS21: 前杭爱省 | BT21: 南戈壁省 | BU21: 苏赫巴托尔省 | BV21: 色楞格省 | BW21: 中央省 | BX21: 乌布苏省 | BY21: 科布多省 | BZ21: 库苏古尔省 | CA21: 肯特省 | CB21: 鄂尔浑省 | CC21: 达尔汗乌勒省 | CD21: 戈壁苏木贝尔省
B22: 罪犯经历包 | C22: 1d10 | D22: 60 | E22: 对目击尸体、目击或亲自谋杀、目击对人类的暴力残害造成的理智损失免疫;初始年龄不能低于 20 岁；背景增加一项：犯罪历史相关的伤疤 / 疤痕或恐惧症 / 躁狂症 | O22: 其他(头) | AA22: =IF(ISBLANK(人物卡!CZ26),0,1) -> 0 | AB22: =IF(ISBLANK(人物卡!DI26),0,1) -> 0 | AC22: =AA21+AA23+AA22+AA25+AA24+AB21+AB22+AB23+AB24+AB25 -> 0 | AD22: =IF(人物卡!CT29="提示当前职业",0,1) -> 0 | AE22: =IF(AD32=1,"仅显示1890_2023",AE28) -> 仅显示1890_2023 | AF22: =IF(AE22="仅显示1890_2023","",VLOOKUP(AE22,AE33:AS166,2,FALSE)) | AG22: =IF(AE22="仅显示1890～2023","",VLOOKUP(AE22,AE33:AS166,3,FALSE)) -> #N/A | AH22: =IF(AE22="仅显示1890～2023","",VLOOKUP(AE22,AE33:AS166,4,FALSE)) -> #N/A | AI22: =IF(AE22="仅显示1890～2023","",VLOOKUP(AE22,AE33:AS166,5,FALSE)) -> #N/A | AJ22: =IF(AE22="仅显示1890～2023","",VLOOKUP(AE22,AE33:AS166,6,FALSE)) -> #N/A | AK22: =IF(AE22="仅显示1890～2023","",VLOOKUP(AE22,AE33:AS166,7,FALSE)) -> #N/A | AL22: =IF(AE22="仅显示1890～2023","",VLOOKUP(AE22,AE33:AS166,8,FALSE)) -> #N/A | AM22: =IF(AE22="仅显示1890～2023","",VLOOKUP(AE22,AE33:AS166,9,FALSE)) -> #N/A | AN22: =IF(AE22="仅显示1890～2023","",VLOOKUP(AE22,AE33:AS166,10,FALSE)) -> #N/A | AO22: =IF(AE22="仅显示1890～2023","",VLOOKUP(AE22,AE33:AS166,11,FALSE)) -> #N/A | AP22: =IF(AE22="仅显示1890～2023","",VLOOKUP(AE22,AE33:AS166,12,FALSE)) -> #N/A | AQ22: =IF(AE22="仅显示1890～2023","",VLOOKUP(AE22,AE33:AS166,13,FALSE)) -> #N/A | AR22: =IF(AE22="仅显示1890～2023","",VLOOKUP(AE22,AE33:AS166,14,FALSE)) -> #N/A | AS22: =IF(AE22="仅显示1890～2023","",VLOOKUP(AE22,AE33:AS166,15,FALSE)) -> #N/A
B23: 医务经历包 | C23: 1d10 | D23: 60 | E23: 对目击尸体和重伤员造成的理智损失免疫;初始年龄不能低于 30 岁；背景增加一项：个人背景相关的伤疤 / 疤痕或恐惧症 / 躁狂症； | O23: 躯———— | Q23: 显露 | AA23: =IF(ISBLANK(人物卡!CZ27),0,1) -> 0 | AB23: =IF(ISBLANK(人物卡!DI27),0,1) -> 0 | AC23: 剩余 | AE23: 目前值 | BH23: *东南亚*
B24: 神话经历包 | C24: 如果是"相信者"，减少和克苏鲁神话相同的san值 | D24: 0 | E24: 按 KP 允许的数值增加「克苏鲁神话」技能;背景增加两项：与神话经历相关的伤疤 /疤痕、恐惧症 / 躁狂症、遭遇的怪异存在 | O24: 肩 | Q24: 隐藏 | S24: =".st "&"力量"&G14&"str"&G14&"敏捷"&J14&"dex"&J14&"意志"&M14&"pow"&M14&"体质"&H14&"con"&H14&"外貌"&K14&"app"&K14&"教育"&N14&"edu"&N14&"体型"&I14&"siz"&I14&"智力"&L14&"灵感"&L14&"int"&L14&"san"&人物卡!BM19&"san值"&人物卡!BM19&"理智"&人物卡!BM19&"理智值"&人物卡!BM19&"幸运"&O14&"运气"&O14&"mp"&人物卡!BV19&"魔法"&人物卡!BV19&"hp"&人物卡!BD19&"体力"&人物卡!BD19&人物卡!BE25&人物卡!BQ25&人物卡!BE26&人物卡!BQ26&人物卡!BE27&人物卡!BQ27&人物卡!BE28&人物卡!BQ28&IF(人物卡!BG29="","",人物卡!BG29&人物卡!BQ29)&IF(人物卡!BG30="","",人物卡!BG30&人物卡!BQ30)&IF(人物卡!BG31="","",人物卡!BG31&人物卡!BQ31)&人物卡!BE32&人物卡!BQ32&"魅惑"&人物卡!BQ32&人物卡!BE33&人物卡!BQ33&"计算机"&人物卡!BQ34&"计算机使用"&人物卡!BQ34&"电脑"&人物卡!BQ34&"信用"&人物卡!BQ35&"信誉"&人物卡!BQ35&"信用评级"&人物卡!BQ35&"克苏鲁"&人物卡!BQ36&"克苏鲁神话"&人物卡!BQ36&"cm"&人物卡!BQ36&人物卡!BE37&人物卡!BQ37&人物卡!BE38&人物卡!BQ38&"汽车"&人物卡!BQ39&"驾驶"&人物卡!BQ39&"汽车驾驶"&人物卡!BQ39&人物卡!BE40&人物卡!BQ40&"电子学"&人物卡!BQ41&人物卡!BE42&人物卡!BQ42&人物卡!BG43&人物卡!BQ43&IF(人物卡!BG44="","",人物卡!BG44&人物卡!BQ44)&IF(人物卡!BG45="","",人物卡!BG45&人物卡!BQ45)&IF(人物卡!BG46="","",人物卡!BG46&人物卡!BQ46)&人物卡!BG47&人物卡!BQ47&IF(W15=1,人物卡!CA48&人物卡!BQ48&"步枪"&人物卡!BQ48&"霰弹枪"&人物卡!BQ48&"步霰"&人物卡!BQ48,IF(人物卡!BG48="","",人物卡!BG48&人物卡!BQ48))&IF(W16=1,人物卡!CA49&人物卡!BQ49&"步枪"&人物卡!BQ49&"霰弹枪"&人物卡!BQ49&"步霰"&人物卡!BQ49,IF(人物卡!BG49="","",人物卡!BG49&人物卡!BQ49))&IF(W17=1,人物卡!CA50&人物卡!BQ50&"步枪"&人物卡!BQ50&"霰弹枪"&人物卡!BQ50&"步霰"&人物卡!BQ50,IF(人物卡!BG50="","",人物卡!BG50&人物卡!BQ50))&人物卡!BE51&人物卡!BQ51&人物卡!BE52&人物卡!BQ52&人物卡!BE53&人物卡!BQ53&人物卡!BE54&人物卡!BQ54&IF(人物卡!BG55="","",人物卡!BG55&人物卡!BQ55)&IF(人物卡!BG56="","",人物卡!BG56&人物卡!BQ56)&IF(人物卡!BG57="","",人物卡!BG57&人物卡!BQ57)&人物卡!BE58&人物卡!BQ58&人物卡!CA25&人物卡!CM25&"图书馆"&人物卡!CM26&"图书馆使用"&人物卡!CM26&人物卡!CA27&人物卡!CM27&"开锁"&人物卡!CM28&"撬锁"&人物卡!CM28&"锁匠"&人物卡!CM28&人物卡!CA29&人物卡!CM29&人物卡!CA30&人物卡!CM30&"博物学"&人物卡!CM31&"自然学"&人物卡!CM31&"领航"&人物卡!CM32&"导航"&人物卡!CM32&人物卡!CA33&人物卡!CM33&"重型操作"&人物卡!CM34&"重型机械"&人物卡!CM34&"操作重型机械"&人物卡!CM34&"重型"&人物卡!CM34&人物卡!CA35&人物卡!CM35&IF(人物卡!CC36="","",人物卡!CC36&人物卡!CM36)&人物卡!CA37&人物卡!CM37&人物卡!CA38&人物卡!CM38&人物卡!CA39&人物卡!CM39&IF(人物卡!CC40="","",人物卡!CC40&人物卡!CM40)&IF(人物卡!CC41="","",人物卡!CC41&人物卡!CM41)&IF(人物卡!CC42="","",人物卡!CC42&人物卡!CM42)&人物卡!CA43&人物卡!CM43&人物卡!CA44&人物卡!CM44&人物卡!CA45&人物卡!CM45&"生存"&人物卡!CM46&人物卡!CA47&人物卡!CM47&人物卡!CA48&人物卡!CM48&人物卡!CA49&人物卡!CM49&人物卡!CA50&人物卡!CM50&人物卡!CA51&人物卡!CM51&人物卡!CA52&人物卡!CM52&人物卡!CA53&人物卡!CM53&人物卡!CA54&人物卡!CM54&人物卡!CA55&人物卡!CM55&IF(人物卡!CC56="","",人物卡!CC56&人物卡!CM56)&IF(W18=1,"",人物卡!CA57&人物卡!CM57)&IF(人物卡!CA58="","",人物卡!CA58&人物卡!CM58) -> .st 力量0str0敏捷0dex0意志0pow0体质0con0外貌0app0教育0edu0体型0siz0智力0灵感0int0san0san值0理智0理智值0幸运0运气0mp0魔法0hp0体力0会计5法律5历史5人类学1神秘学5魅惑5信用评级0计算机0计算机使用0电脑0信用10信誉10信用评级10克苏鲁10克苏鲁神话10cm10电子学 Ω1操作重型机械1汽车1驾驶1汽车驾驶1计算机使用 Ω0电子学1科学②115技艺⑤5母语0外语①1外语②1闪避0锁匠1图书馆5图书馆使用5妙手10开锁20撬锁20锁匠20图书馆使用20聆听20博物学25自然学25领航10导航10导航10重型操作10重型机械10操作重型机械10重型10取悦15恐吓15说服10跳跃20游泳20精神分析1医学1生存30驾驶①1驾驶②1汽车驾驶20骑术5动物驯养5潜水1读唇1催眠1自定义①1炮术1投掷20 | AA24: =IF(ISBLANK(人物卡!CZ28),0,1) -> 0 | AB24: =IF(ISBLANK(人物卡!DI28),0,1) -> 0 | AC24: =人物卡!BE18-AC22 -> 0 | AE24: =人物卡!BF17 -> 0 | AX24: 总值 | AZ24: 分类 | BH24: 越南 | BI24: 河内市* | BJ24: 胡志明市 | BK24: 岘港市 | BL24: 海防市 | BM24: 芹苴市 | BN24: 安江省 | BO24: 北江省 | BP24: 北件省 | BQ24: 北宁省 | BR24: 薄辽省 | BS24: 北𣴓省 | BT24: 巴地-头顿省 | BU24: 槟椥省 | BV24: 平定省 | BW24: 平阳省 | BX24: 平福省 | BY24: 平顺省 | BZ24: 富安省 | CA24: 富寿省 | CB24: 高平省 | CC24: 广安省 | CD24: 广宁省 | CE24: 广平省 | CF24: 广南省 | CG24: 广义省 | CH24: 广治省 | CI24: 河南省 | CJ24: 和平省 | CK24: 后江省 | CL24: 海阳省 | CM24: 海防市 | CN24: 河江省 | CO24: 河静省 | CP24: 河北省 | CQ24: 河东省 | CR24: 河西省 | CS24: 兴安省 | CT24: 坚江省 | CU24: 嘉莱省 | CV24: 昆嵩省 | CW24: 莱州省 | CX24: 林同省 | CY24: 谅山省 | CZ24: 隆安省 | DA24: 南定省 | DB24: 宁平省 | DC24: 宁顺省 | DD24: 义安省 | DE24: 前江省 | DF24: 芹苴市 | DG24: 清化省 | DH24: 庆和省 | DI24: 山罗省 | DJ24: 山西省 | DK24: 西宁省 | DL24: 太平省 | DM24: 太原省 | DN24: 同奈省 | DO24: 同塔省 | DP24: 宣光省 | DQ24: 永福省 | DR24: 永隆省 | DS24: 安沛省
B25: =IF(ISBLANK(人物卡!AF108),"自定义经历包",人物卡!AF108) -> 自定义经历包 | C25: ='简化卡 骰娘导入'!E96 | D25: ='简化卡 骰娘导入'!H96 | E25: ='简化卡 骰娘导入'!J96 | O25: 胸前 | X25: 会计 | AB25: =IF(ISBLANK(人物卡!DI29),0,1) -> 0 | AC25: 最终显示 | AD25: =IF(AD22=1," ",IF(AC24=0,"无",IF(AC24<0,"过多！",AC24))) -> 无 | AE25: 公元调整 | AT25: 未出现的 | AV25: =IF(AT25=人物卡!CY93,1,0) -> 0 | AZ25: 1 | BA25: 未出现的发明 | BB25: =AQ22 -> #N/A | BH25: 老挝 | BI25: 万象市* | BJ25: 波里坎赛省 | BK25: 博胶省 | BL25: 川圹省 | BM25: 甘蒙省 | BN25: 华潘省 | BO25: 琅勃拉邦省 | BP25: 琅南塔省 | BQ25: 丰沙里省 | BR25: 乌多姆赛省 | BS25: 沙耶武里省 | BT25: 沙湾拿吉省 | BU25: 色贡省 | BV25: 沙拉湾省 | BW25: 赛宋本行政特区 | BX25: 万象省 | BY25: 占巴塞省
B26: 无 | O26: 背后 | X26: 法律 | AE26: =IF(人物卡!BD17="公元前",人物卡!BF17*2,0) -> 0 | AT26: 已出现的 | AV26: =IF(AT26=人物卡!CY93,2,0) -> 2 | AZ26: 2 | BA26: 已出现的发明 | BB26: =AR22 -> #N/A | BH26: 柬埔寨 | BI26: 金边直辖市* | BJ26: 马德望省 | BK26: 磅湛省 | BL26: 磅清扬省 | BM26: 磅士卑省 | BN26: 磅同省 | BO26: 贡布省 | BP26: 干丹省 | BQ26: 茶胶省 | BR26: 柴桢省 | BS26: 波萝勉省 | BT26: 菩萨省 | BU26: 西哈努克省 | BV26: 柏威夏省 | BW26: 上丁省 | BX26: 桔井省 | BY26: 腊塔纳基里省 | BZ26: 蒙多基里省
C27: =IF(人物卡!BE148=B20,C20,0) -> 0 | D27: =IF(人物卡!BE148=B20,D20,0) -> 0 | E27: =IF(人物卡!BE148=B20,E20,0) -> 0 | O27: 肋 | X27: 历史 | AB27: 经历包剩余点 | AC27: =D34-SUM(人物卡!BK25:BK58,人物卡!CG25:CG58) -> #VALUE! | AD27: 最终值 | AE27: 调整出目 | AX27: =AV25+AV26+AV28+AV29+AV30 -> 2 | AZ27: 3 | BA27: 本年的发明 | BB27: =AS22 -> #N/A | BH27: 泰国 | BI27: 曼谷直辖市* | BJ27: 清迈府 | BK27: 清莱府 | BL27: 甘烹碧府 | BM27: 南邦府 | BN27: 南奔府 | BO27: 夜丰颂府 | BP27: 北榄坡府 | BQ27: 楠府 | BR27: 帕尧府 | BS27: 碧差汶府 | BT27: 披集府 | BU27: 彭世洛府 | BV27: 帕府 | BW27: 素可泰府 | BX27: 达府 | BY27: 乌泰他尼府 | BZ27: 程逸府 | CA27: 安纳乍能府 | CB27: 武里南府 | CC27: 猜也奔府 | CD27: 加拉信府 | CE27: 孔敬府 | CF27: 黎府 | CG27: 玛哈沙拉堪府 | CH27: 莫拉限府 | CI27: 那空帕侬府 | CJ27: 呵叻府 | CK27: 廊磨喃蒲府 | CL27: 廊开府 | CM27: 横逸府 | CN27: 色军府 | CO27: 四色菊府 | CP27: 素辇府 | CQ27: 乌汶府 | CR27: 乌隆他尼府 | CS27: 益梭通府 | CT27: 汶干府 | CU27: 北柳府 | CV27: 尖竹汶府 | CW27: 春武里府 | CX27: 巴真府 | CY27: 罗勇府 | CZ27: 沙缴府 | DA27: 达叻府 | DB27: 红统府 | DC27: 大城府 | DD27: 猜纳府 | DE27: 北碧府 | DF27: 华富里府 | DG27: 那空那育府 | DH27: 佛统府 | DI27: 暖武里府 | DJ27: 巴吞他尼府 | DK27: 佛丕府 | DL27: 班武里府 | DM27: 叻丕府 | DN27: 北榄府 | DO27: 龙仔厝府 | DP27: 夜功府 | DQ27: 北标府 | DR27: 信武里府 | DS27: 素攀府 | DT27: 洛坤府 | DU27: 甲米府 | DV27: 攀牙府 | DW27: 普吉府 | DX27: 素叻他尼府 | DY27: 拉侬府 | DZ27: 春蓬府 | EA27: 宋卡府 | EB27: 沙敦府 | EC27: 董里府 | ED27: 博达伦府 | EE27: 北大年府 | EF27: 也拉府 | EG27: 陶公府
C28: =IF(人物卡!BE148=B21,C21,0) -> 0 | D28: =IF(人物卡!BE148=B21,D21,0) -> 0 | E28: =IF(人物卡!BE148=B21,E21,0) -> 0 | O28: 裆 | X28: 人类学 | AB28: 检测是否为数字 | AC28: =ISNUMBER(AC27) -> FALSE | AD28: =IF(AC28=FALSE,"0",AC27) -> 0 | AE28: =AE24-AE26 -> 0 | AT28: 本年的发明 | AV28: =IF(AT28=人物卡!CY93,3,0) -> 0 | AZ28: 4 | BA28: 查找年份发明 | BB28: =AS21 -> 纸制鸡蛋托 面巾纸 | BH28: 缅甸 | BI28: 内比都联邦区* | BJ28: 仰光省 | BK28: 曼德勒省 | BL28: 马圭省 | BM28: 实皆省 | BN28: 伊洛瓦底省 | BO28: 德林达依省 | BP28: 勃固省 | BQ28: 若开邦 | BR28: 钦邦 | BS28: 掸邦 | BT28: 克耶邦 | BU28: 克伦邦 | BV28: 孟邦 | BW28: 克钦邦
C29: =IF(人物卡!BE148=B22,C22,0) -> 0 | D29: =IF(人物卡!BE148=B22,D22,0) -> 0 | E29: =IF(人物卡!BE148=B22,E22,0) -> 0 | O29: 腰 | X29: 估价 | AB29: 职业点数 | AC29: =IF(人物卡!BL11=0," ",LOOKUP(人物卡!BL11,职业列表!A2:C237,职业列表!F2:F237)) | AD29: 检测大小 | AT29: 查找年份发明 | AV29: =IF(AT29=人物卡!CY93,4,0) -> 0 | AZ29: 5 | BA29: 查找发明的时间 | BB29: ? | BH29: 马来西亚 | BI29: 吉隆坡联邦直辖区* | BJ29: 玻璃市州 | BK29: 吉打州 | BL29: 吉兰丹州 | BM29: 槟城州 | BN29: 霹雳州 | BO29: 雪兰莪州 | BP29: 森美兰州 | BQ29: 马六甲州 | BR29: 柔佛州 | BS29: 彭亨州 | BT29: 登嘉楼州 | BU29: 沙巴州 | BV29: 砂拉越州 | BW29: 布城联邦直辖区 | BX29: 纳闽联邦直辖区
C30: =IF(人物卡!BE148=B23,C23,0) -> 0 | D30: =IF(人物卡!BE148=B23,D23,0) -> 0 | E30: =IF(人物卡!BE148=B23,E23,0) -> 0 | O30: 胯 | X30: 考古学 | AD30: =IF(AE30="大",1,0) -> 0 | AE30: =IF(AE28>2023,"大") -> FALSE | AT30: 研发中... | AU30: 查找发明的时间 | AV30: =IF(AU30=人物卡!CY93,5,0) -> 0 | BH30: 新加坡 | BI30: 新加坡市
